2018-09-16 00:10:56,695 [Thread-1:6696] [django.server:124] [basehttp:log_message] [INFO]- "POST /api/add_event/ HTTP/1.1" 200 48
2018-09-16 00:10:57,775 [Thread-3:8792] [django.server:124] [basehttp:log_message] [INFO]- "POST /api/add_event/ HTTP/1.1" 200 56
2018-09-16 00:10:58,841 [Thread-4:6804] [django.server:124] [basehttp:log_message] [INFO]- "POST /api/add_event/ HTTP/1.1" 200 58
2018-09-16 00:11:35,364 [Thread-5:3320] [django.server:124] [basehttp:log_message] [INFO]- "POST /api/add_event/ HTTP/1.1" 200 56
2018-09-16 00:11:36,426 [Thread-6:8328] [django.server:124] [basehttp:log_message] [INFO]- "POST /api/add_event/ HTTP/1.1" 200 56
2018-09-16 00:11:37,490 [Thread-7:4340] [django.server:124] [basehttp:log_message] [INFO]- "POST /api/add_event/ HTTP/1.1" 200 58
2018-09-16 00:16:05,947 [Thread-8:8796] [django.server:124] [basehttp:log_message] [INFO]- "POST /api/add_event/ HTTP/1.1" 200 56
2018-09-16 00:16:07,028 [Thread-9:8844] [django.server:124] [basehttp:log_message] [INFO]- "POST /api/add_event/ HTTP/1.1" 200 56
2018-09-16 00:16:08,091 [Thread-10:7108] [django.server:124] [basehttp:log_message] [INFO]- "POST /api/add_event/ HTTP/1.1" 200 58
2018-09-16 00:17:21,278 [Thread-11:8436] [django.server:124] [basehttp:log_message] [INFO]- "POST /api/add_event/ HTTP/1.1" 200 56
2018-09-16 00:17:22,376 [Thread-12:7964] [django.server:124] [basehttp:log_message] [INFO]- "POST /api/add_event/ HTTP/1.1" 200 56
2018-09-16 00:17:23,500 [Thread-13:8928] [django.server:124] [basehttp:log_message] [INFO]- "POST /api/add_event/ HTTP/1.1" 200 58
2018-09-16 00:17:41,939 [Thread-14:5248] [django.server:124] [basehttp:log_message] [INFO]- "POST /api/add_event/ HTTP/1.1" 200 56
2018-09-16 00:17:43,044 [Thread-15:7212] [django.server:124] [basehttp:log_message] [INFO]- "POST /api/add_event/ HTTP/1.1" 200 56
2018-09-16 00:17:44,165 [Thread-16:8796] [django.server:124] [basehttp:log_message] [INFO]- "POST /api/add_event/ HTTP/1.1" 200 58
2018-09-16 00:20:16,908 [Thread-17:4644] [django.server:124] [basehttp:log_message] [INFO]- "GET /api/get_event_list/?name=%E5%B0%8F%E7%B1%B3w HTTP/1.1" 200 54
2018-09-16 00:20:22,639 [Thread-18:4636] [django.server:124] [basehttp:log_message] [INFO]- "GET /api/get_event_list/?name=%E5%B0%8F%E7%B1%B3 HTTP/1.1" 200 547
2018-09-16 09:09:19,837 [Thread-1:4836] [django.server:124] [basehttp:log_message] [INFO]- "GET /api/add_guest HTTP/1.1" 301 0
2018-09-16 09:09:19,852 [Thread-3:720] [django.server:124] [basehttp:log_message] [INFO]- "GET /api/add_guest/ HTTP/1.1" 200 48
2018-09-16 09:12:28,471 [Thread-6:5488] [django.server:124] [basehttp:log_message] [INFO]- "POST /api/add_guest/ HTTP/1.1" 200 48
2018-09-16 09:20:08,323 [Thread-1:9176] [log:83] [views_api:add_guest] [INFO]- 参数错误，不能为空.
2018-09-16 09:20:08,326 [Thread-1:9176] [django.server:124] [basehttp:log_message] [INFO]- "POST /api/add_guest/ HTTP/1.1" 200 48
2018-09-16 09:21:38,779 [Thread-3:8760] [django.request:135] [exception:handle_uncaught_exception] [ERROR]- Internal Server Error: /api/add_guest/
Traceback (most recent call last):
  File "D:\python3.6.5\lib\site-packages\django\core\handlers\exception.py", line 41, in inner
    response = get_response(request)
  File "D:\python3.6.5\lib\site-packages\django\core\handlers\base.py", line 187, in _get_response
    response = self.process_exception_by_middleware(e, request)
  File "D:\python3.6.5\lib\site-packages\django\core\handlers\base.py", line 185, in _get_response
    response = wrapped_callback(request, *callback_args, **callback_kwargs)
  File "D:\tester\guest\sign\views_api.py", line 102, in add_guest
    timeArray = time.strptime(etime, '%Y-%m-%d %H:%M:%S')
  File "D:\python3.6.5\lib\_strptime.py", line 559, in _strptime_time
    tt = _strptime(data_string, format)[0]
  File "D:\python3.6.5\lib\_strptime.py", line 365, in _strptime
    data_string[found.end():])
ValueError: unconverted data remains: +00:00
2018-09-16 09:21:39,092 [Thread-3:8760] [django.server:124] [basehttp:log_message] [ERROR]- "POST /api/add_guest/ HTTP/1.1" 500 76887
2018-09-16 09:25:09,442 [Thread-4:3736] [django.request:135] [exception:handle_uncaught_exception] [ERROR]- Internal Server Error: /api/add_guest/
Traceback (most recent call last):
  File "D:\python3.6.5\lib\site-packages\django\core\handlers\exception.py", line 41, in inner
    response = get_response(request)
  File "D:\python3.6.5\lib\site-packages\django\core\handlers\base.py", line 187, in _get_response
    response = self.process_exception_by_middleware(e, request)
  File "D:\python3.6.5\lib\site-packages\django\core\handlers\base.py", line 185, in _get_response
    response = wrapped_callback(request, *callback_args, **callback_kwargs)
  File "D:\tester\guest\sign\views_api.py", line 102, in add_guest
    timeArray = time.strptime(etime, '%Y-%m-%d %H:%M:%S')
  File "D:\python3.6.5\lib\_strptime.py", line 559, in _strptime_time
    tt = _strptime(data_string, format)[0]
  File "D:\python3.6.5\lib\_strptime.py", line 365, in _strptime
    data_string[found.end():])
ValueError: unconverted data remains: +00:00
2018-09-16 09:25:09,512 [Thread-4:3736] [django.server:124] [basehttp:log_message] [ERROR]- "POST /api/add_guest/ HTTP/1.1" 500 77035
2018-09-16 09:27:28,675 [Thread-5:9032] [django.request:135] [exception:handle_uncaught_exception] [ERROR]- Internal Server Error: /api/add_guest/
Traceback (most recent call last):
  File "D:\python3.6.5\lib\site-packages\django\core\handlers\exception.py", line 41, in inner
    response = get_response(request)
  File "D:\python3.6.5\lib\site-packages\django\core\handlers\base.py", line 187, in _get_response
    response = self.process_exception_by_middleware(e, request)
  File "D:\python3.6.5\lib\site-packages\django\core\handlers\base.py", line 185, in _get_response
    response = wrapped_callback(request, *callback_args, **callback_kwargs)
  File "D:\tester\guest\sign\views_api.py", line 102, in add_guest
    timeArray = time.strptime(etime, '%Y-%m-%d %H:%M:%S')
  File "D:\python3.6.5\lib\_strptime.py", line 559, in _strptime_time
    tt = _strptime(data_string, format)[0]
  File "D:\python3.6.5\lib\_strptime.py", line 365, in _strptime
    data_string[found.end():])
ValueError: unconverted data remains: +00:00
2018-09-16 09:27:28,740 [Thread-5:9032] [django.server:124] [basehttp:log_message] [ERROR]- "POST /api/add_guest/ HTTP/1.1" 500 77035
2018-09-16 09:28:46,822 [Thread-1:7224] [log:102] [views_api:add_guest] [INFO]- 2018-09-15 09:31:00+00:00
2018-09-16 09:28:46,827 [Thread-1:7224] [django.request:135] [exception:handle_uncaught_exception] [ERROR]- Internal Server Error: /api/add_guest/
Traceback (most recent call last):
  File "D:\python3.6.5\lib\site-packages\django\core\handlers\exception.py", line 41, in inner
    response = get_response(request)
  File "D:\python3.6.5\lib\site-packages\django\core\handlers\base.py", line 187, in _get_response
    response = self.process_exception_by_middleware(e, request)
  File "D:\python3.6.5\lib\site-packages\django\core\handlers\base.py", line 185, in _get_response
    response = wrapped_callback(request, *callback_args, **callback_kwargs)
  File "D:\tester\guest\sign\views_api.py", line 103, in add_guest
    timeArray = time.strptime(etime, '%Y-%m-%d %H:%M:%S')
  File "D:\python3.6.5\lib\_strptime.py", line 559, in _strptime_time
    tt = _strptime(data_string, format)[0]
  File "D:\python3.6.5\lib\_strptime.py", line 365, in _strptime
    data_string[found.end():])
ValueError: unconverted data remains: +00:00
2018-09-16 09:28:47,074 [Thread-1:7224] [django.server:124] [basehttp:log_message] [ERROR]- "POST /api/add_guest/ HTTP/1.1" 500 76968
2018-09-16 09:29:30,600 [Thread-1:6060] [log:102] [views_api:add_guest] [INFO]- ['2018-09-15 09:31:00+00:00']
2018-09-16 09:29:30,607 [Thread-1:6060] [django.request:135] [exception:handle_uncaught_exception] [ERROR]- Internal Server Error: /api/add_guest/
Traceback (most recent call last):
  File "D:\python3.6.5\lib\site-packages\django\core\handlers\exception.py", line 41, in inner
    response = get_response(request)
  File "D:\python3.6.5\lib\site-packages\django\core\handlers\base.py", line 187, in _get_response
    response = self.process_exception_by_middleware(e, request)
  File "D:\python3.6.5\lib\site-packages\django\core\handlers\base.py", line 185, in _get_response
    response = wrapped_callback(request, *callback_args, **callback_kwargs)
  File "D:\tester\guest\sign\views_api.py", line 103, in add_guest
    timeArray = time.strptime(etime, '%Y-%m-%d %H:%M:%S')
  File "D:\python3.6.5\lib\_strptime.py", line 559, in _strptime_time
    tt = _strptime(data_string, format)[0]
  File "D:\python3.6.5\lib\_strptime.py", line 329, in _strptime
    raise TypeError(msg.format(index, type(arg)))
TypeError: strptime() argument 0 must be str, not <class 'list'>
2018-09-16 09:29:30,883 [Thread-1:6060] [django.server:124] [basehttp:log_message] [ERROR]- "POST /api/add_guest/ HTTP/1.1" 500 76588
2018-09-16 09:30:24,415 [Thread-1:4216] [log:101] [views_api:add_guest] [INFO]- 2018-09-15 09:31:00+00:00
2018-09-16 09:30:24,415 [Thread-1:4216] [log:103] [views_api:add_guest] [INFO]- ['2018-09-15 09:31:00+00:00']
2018-09-16 09:30:24,418 [Thread-1:4216] [django.request:135] [exception:handle_uncaught_exception] [ERROR]- Internal Server Error: /api/add_guest/
Traceback (most recent call last):
  File "D:\python3.6.5\lib\site-packages\django\core\handlers\exception.py", line 41, in inner
    response = get_response(request)
  File "D:\python3.6.5\lib\site-packages\django\core\handlers\base.py", line 187, in _get_response
    response = self.process_exception_by_middleware(e, request)
  File "D:\python3.6.5\lib\site-packages\django\core\handlers\base.py", line 185, in _get_response
    response = wrapped_callback(request, *callback_args, **callback_kwargs)
  File "D:\tester\guest\sign\views_api.py", line 104, in add_guest
    timeArray = time.strptime(etime, '%Y-%m-%d %H:%M:%S')
  File "D:\python3.6.5\lib\_strptime.py", line 559, in _strptime_time
    tt = _strptime(data_string, format)[0]
  File "D:\python3.6.5\lib\_strptime.py", line 329, in _strptime
    raise TypeError(msg.format(index, type(arg)))
TypeError: strptime() argument 0 must be str, not <class 'list'>
2018-09-16 09:30:24,659 [Thread-1:4216] [django.server:124] [basehttp:log_message] [ERROR]- "POST /api/add_guest/ HTTP/1.1" 500 76570
2018-09-16 09:34:50,162 [Thread-3:1528] [django.server:124] [basehttp:log_message] [INFO]- "GET /admin HTTP/1.1" 301 0
2018-09-16 09:34:50,313 [Thread-4:7264] [django.server:124] [basehttp:log_message] [INFO]- "GET /admin/ HTTP/1.1" 200 6682
2018-09-16 09:34:50,418 [Thread-5:5144] [django.server:124] [basehttp:log_message] [INFO]- "GET /static/admin/css/base.css HTTP/1.1" 200 16066
2018-09-16 09:34:50,653 [Thread-6:4792] [django.server:124] [basehttp:log_message] [INFO]- "GET /static/admin/css/dashboard.css HTTP/1.1" 200 412
2018-09-16 09:34:50,743 [Thread-7:7500] [django.server:124] [basehttp:log_message] [INFO]- "GET /static/admin/css/fonts.css HTTP/1.1" 200 423
2018-09-16 09:34:51,084 [Thread-8:2992] [django.server:124] [basehttp:log_message] [INFO]- "GET /static/admin/fonts/Roboto-Light-webfont.woff HTTP/1.1" 200 81348
2018-09-16 09:34:51,084 [Thread-10:8792] [django.server:124] [basehttp:log_message] [INFO]- "GET /static/admin/fonts/Roboto-Regular-webfont.woff HTTP/1.1" 200 80304
2018-09-16 09:34:51,085 [Thread-9:6872] [django.server:124] [basehttp:log_message] [INFO]- "GET /static/admin/fonts/Roboto-Bold-webfont.woff HTTP/1.1" 200 82564
2018-09-16 09:34:51,087 [Thread-11:6776] [django.server:124] [basehttp:log_message] [INFO]- "GET /static/admin/img/icon-addlink.svg HTTP/1.1" 200 331
2018-09-16 09:34:51,091 [Thread-12:5460] [django.server:124] [basehttp:log_message] [INFO]- "GET /static/admin/img/icon-changelink.svg HTTP/1.1" 200 380
2018-09-16 09:34:54,237 [Thread-13:8744] [django.server:124] [basehttp:log_message] [INFO]- "GET /admin/sign/event/ HTTP/1.1" 200 10572
2018-09-16 09:34:54,442 [Thread-14:7348] [django.server:124] [basehttp:log_message] [INFO]- "GET /static/admin/css/changelists.css HTTP/1.1" 200 6170
2018-09-16 09:34:54,579 [Thread-16:9096] [django.server:124] [basehttp:log_message] [INFO]- "GET /static/admin/js/core.js HTTP/1.1" 200 7976
2018-09-16 09:34:54,585 [Thread-18:2976] [django.server:124] [basehttp:log_message] [INFO]- "GET /static/admin/js/jquery.init.js HTTP/1.1" 200 363
2018-09-16 09:34:54,588 [Thread-15:5332] [django.server:124] [basehttp:log_message] [INFO]- "GET /admin/jsi18n/ HTTP/1.1" 200 7682
2018-09-16 09:34:54,589 [Thread-19:4084] [django.server:124] [basehttp:log_message] [INFO]- "GET /static/admin/js/admin/RelatedObjectLookups.js HTTP/1.1" 200 6591
2018-09-16 09:34:54,637 [Thread-17:6460] [django.server:124] [basehttp:log_message] [INFO]- "GET /static/admin/js/vendor/jquery/jquery.js HTTP/1.1" 200 258648
2018-09-16 09:34:54,752 [Thread-20:7036] [django.server:124] [basehttp:log_message] [INFO]- "GET /static/admin/js/actions.js HTTP/1.1" 200 6501
2018-09-16 09:34:54,892 [Thread-21:7640] [django.server:124] [basehttp:log_message] [INFO]- "GET /static/admin/js/urlify.js HTTP/1.1" 200 8186
2018-09-16 09:34:54,899 [Thread-22:7928] [django.server:124] [basehttp:log_message] [INFO]- "GET /static/admin/js/prepopulate.js HTTP/1.1" 200 1538
2018-09-16 09:34:54,911 [Thread-23:7388] [django.server:124] [basehttp:log_message] [INFO]- "GET /static/admin/js/vendor/xregexp/xregexp.js HTTP/1.1" 200 128820
2018-09-16 09:34:54,940 [Thread-24:8564] [django.server:124] [basehttp:log_message] [INFO]- "GET /static/admin/img/search.svg HTTP/1.1" 200 458
2018-09-16 09:34:54,950 [Thread-25:8440] [django.server:124] [basehttp:log_message] [INFO]- "GET /static/admin/img/icon-no.svg HTTP/1.1" 200 560
2018-09-16 09:34:55,233 [Thread-26:7100] [django.server:124] [basehttp:log_message] [INFO]- "GET /static/admin/img/icon-yes.svg HTTP/1.1" 200 436
2018-09-16 09:34:55,242 [Thread-27:6452] [django.server:124] [basehttp:log_message] [INFO]- "GET /static/admin/img/tooltag-add.svg HTTP/1.1" 200 331
2018-09-16 09:35:30,555 [Thread-28:6804] [django.server:124] [basehttp:log_message] [INFO]- "GET /admin/ HTTP/1.1" 200 6682
2018-09-16 09:35:32,873 [Thread-29:8364] [django.server:124] [basehttp:log_message] [INFO]- "GET /admin/sign/event/add/ HTTP/1.1" 200 6003
2018-09-16 09:35:32,893 [Thread-30:684] [django.server:124] [basehttp:log_message] [INFO]- "GET /static/admin/css/forms.css HTTP/1.1" 200 8173
2018-09-16 09:35:33,201 [Thread-31:5476] [django.server:124] [basehttp:log_message] [INFO]- "GET /static/admin/css/widgets.css HTTP/1.1" 200 10340
2018-09-16 09:35:33,216 [Thread-34:2928] [django.server:124] [basehttp:log_message] [INFO]- "GET /static/admin/js/admin/DateTimeShortcuts.js HTTP/1.1" 200 20529
2018-09-16 09:35:33,216 [Thread-35:6368] [django.server:124] [basehttp:log_message] [INFO]- "GET /static/admin/js/change_form.js HTTP/1.1" 200 712
2018-09-16 09:35:33,217 [Thread-36:7608] [django.server:124] [basehttp:log_message] [INFO]- "GET /static/admin/js/prepopulate_init.js HTTP/1.1" 200 495
2018-09-16 09:35:33,223 [Thread-33:3712] [django.server:124] [basehttp:log_message] [INFO]- "GET /static/admin/js/calendar.js HTTP/1.1" 200 7790
2018-09-16 09:35:33,233 [Thread-32:5412] [django.server:124] [basehttp:log_message] [INFO]- "GET /admin/jsi18n/ HTTP/1.1" 200 7682
2018-09-16 09:35:33,714 [Thread-37:5836] [django.server:124] [basehttp:log_message] [INFO]- "GET /static/admin/img/icon-calendar.svg HTTP/1.1" 200 1086
2018-09-16 09:35:33,714 [Thread-38:8608] [django.server:124] [basehttp:log_message] [INFO]- "GET /static/admin/img/icon-clock.svg HTTP/1.1" 200 677
2018-09-16 09:36:35,097 [Thread-40:7132] [django.server:124] [basehttp:log_message] [INFO]- "POST /admin/sign/event/add/ HTTP/1.1" 302 0
2018-09-16 09:36:35,192 [Thread-41:3832] [django.server:124] [basehttp:log_message] [INFO]- "GET /admin/sign/event/ HTTP/1.1" 200 11275
2018-09-16 09:36:35,238 [Thread-42:3484] [django.server:124] [basehttp:log_message] [INFO]- "GET /admin/jsi18n/ HTTP/1.1" 200 7682
2018-09-16 09:38:27,061 [Thread-3:6424] [log:103] [views_api:add_guest] [INFO]- 2018-09-15 09:31:00+00:00
2018-09-16 09:38:27,062 [Thread-3:6424] [log:105] [views_api:add_guest] [INFO]- 2018-09-15 09:31:00+00:00
2018-09-16 09:38:27,069 [Thread-3:6424] [django.request:135] [exception:handle_uncaught_exception] [ERROR]- Internal Server Error: /api/add_guest/
Traceback (most recent call last):
  File "D:\python3.6.5\lib\site-packages\django\core\handlers\exception.py", line 41, in inner
    response = get_response(request)
  File "D:\python3.6.5\lib\site-packages\django\core\handlers\base.py", line 187, in _get_response
    response = self.process_exception_by_middleware(e, request)
  File "D:\python3.6.5\lib\site-packages\django\core\handlers\base.py", line 185, in _get_response
    response = wrapped_callback(request, *callback_args, **callback_kwargs)
  File "D:\tester\guest\sign\views_api.py", line 106, in add_guest
    timeArray = time.strptime(etime, '%Y-%m-%d %H:%M:%S')
  File "D:\python3.6.5\lib\_strptime.py", line 559, in _strptime_time
    tt = _strptime(data_string, format)[0]
  File "D:\python3.6.5\lib\_strptime.py", line 365, in _strptime
    data_string[found.end():])
ValueError: unconverted data remains: +00:00
2018-09-16 09:38:27,331 [Thread-3:6424] [django.server:124] [basehttp:log_message] [ERROR]- "POST /api/add_guest/ HTTP/1.1" 500 76862
2018-09-16 09:39:03,845 [Thread-1:3612] [log:103] [views_api:add_guest] [INFO]- 2018-09-15 09:31:00+00:00
2018-09-16 09:39:03,847 [Thread-1:3612] [log:105] [views_api:add_guest] [INFO]- 2018-09-15 09:31:00+00:00
2018-09-16 09:39:03,857 [Thread-1:3612] [django.request:135] [exception:handle_uncaught_exception] [ERROR]- Internal Server Error: /api/add_guest/
Traceback (most recent call last):
  File "D:\python3.6.5\lib\site-packages\django\core\handlers\exception.py", line 41, in inner
    response = get_response(request)
  File "D:\python3.6.5\lib\site-packages\django\core\handlers\base.py", line 187, in _get_response
    response = self.process_exception_by_middleware(e, request)
  File "D:\python3.6.5\lib\site-packages\django\core\handlers\base.py", line 185, in _get_response
    response = wrapped_callback(request, *callback_args, **callback_kwargs)
  File "D:\tester\guest\sign\views_api.py", line 106, in add_guest
    timeArray = time.strptime(etime, '%Y-%m-%d %H:%M:%S')
  File "D:\python3.6.5\lib\_strptime.py", line 559, in _strptime_time
    tt = _strptime(data_string, format)[0]
  File "D:\python3.6.5\lib\_strptime.py", line 365, in _strptime
    data_string[found.end():])
ValueError: unconverted data remains: +00:00
2018-09-16 09:39:04,082 [Thread-1:3612] [django.server:124] [basehttp:log_message] [ERROR]- "POST /api/add_guest/ HTTP/1.1" 500 76867
2018-09-16 09:39:41,665 [Thread-1:7028] [log:102] [views_api:add_guest] [INFO]- 2018-09-15 09:31:00+00:00
2018-09-16 09:39:41,665 [Thread-1:7028] [log:106] [views_api:add_guest] [INFO]- 2018-09-15 09:31:00+00:00
2018-09-16 09:39:41,671 [Thread-1:7028] [django.request:135] [exception:handle_uncaught_exception] [ERROR]- Internal Server Error: /api/add_guest/
Traceback (most recent call last):
  File "D:\python3.6.5\lib\site-packages\django\core\handlers\exception.py", line 41, in inner
    response = get_response(request)
  File "D:\python3.6.5\lib\site-packages\django\core\handlers\base.py", line 187, in _get_response
    response = self.process_exception_by_middleware(e, request)
  File "D:\python3.6.5\lib\site-packages\django\core\handlers\base.py", line 185, in _get_response
    response = wrapped_callback(request, *callback_args, **callback_kwargs)
  File "D:\tester\guest\sign\views_api.py", line 107, in add_guest
    timeArray = time.strptime(etime, '%Y-%m-%d %H:%M:%S')
  File "D:\python3.6.5\lib\_strptime.py", line 559, in _strptime_time
    tt = _strptime(data_string, format)[0]
  File "D:\python3.6.5\lib\_strptime.py", line 365, in _strptime
    data_string[found.end():])
ValueError: unconverted data remains: +00:00
2018-09-16 09:39:41,933 [Thread-1:7028] [django.server:124] [basehttp:log_message] [ERROR]- "POST /api/add_guest/ HTTP/1.1" 500 76872
2018-09-16 09:40:03,647 [Thread-1:6792] [log:104] [views_api:add_guest] [INFO]- 2018-09-15 09:31:00+00:00
2018-09-16 09:40:03,648 [Thread-1:6792] [log:107] [views_api:add_guest] [INFO]- 2018-09-15 09:31:00+00:00
2018-09-16 09:40:03,653 [Thread-1:6792] [django.request:135] [exception:handle_uncaught_exception] [ERROR]- Internal Server Error: /api/add_guest/
Traceback (most recent call last):
  File "D:\python3.6.5\lib\site-packages\django\core\handlers\exception.py", line 41, in inner
    response = get_response(request)
  File "D:\python3.6.5\lib\site-packages\django\core\handlers\base.py", line 187, in _get_response
    response = self.process_exception_by_middleware(e, request)
  File "D:\python3.6.5\lib\site-packages\django\core\handlers\base.py", line 185, in _get_response
    response = wrapped_callback(request, *callback_args, **callback_kwargs)
  File "D:\tester\guest\sign\views_api.py", line 108, in add_guest
    timeArray = time.strptime(etime, '%Y-%m-%d %H:%M:%S')
  File "D:\python3.6.5\lib\_strptime.py", line 559, in _strptime_time
    tt = _strptime(data_string, format)[0]
  File "D:\python3.6.5\lib\_strptime.py", line 365, in _strptime
    data_string[found.end():])
ValueError: unconverted data remains: +00:00
2018-09-16 09:40:03,864 [Thread-1:6792] [django.server:124] [basehttp:log_message] [ERROR]- "POST /api/add_guest/ HTTP/1.1" 500 76800
2018-09-16 09:40:41,796 [Thread-1:6364] [log:104] [views_api:add_guest] [INFO]- 2018-09-15 09:31:00+00:00
2018-09-16 09:40:41,796 [Thread-1:6364] [log:107] [views_api:add_guest] [INFO]- 2018-09-15 09:31:00+00:00
2018-09-16 09:40:41,800 [Thread-1:6364] [django.request:135] [exception:handle_uncaught_exception] [ERROR]- Internal Server Error: /api/add_guest/
Traceback (most recent call last):
  File "D:\python3.6.5\lib\site-packages\django\core\handlers\exception.py", line 41, in inner
    response = get_response(request)
  File "D:\python3.6.5\lib\site-packages\django\core\handlers\base.py", line 187, in _get_response
    response = self.process_exception_by_middleware(e, request)
  File "D:\python3.6.5\lib\site-packages\django\core\handlers\base.py", line 185, in _get_response
    response = wrapped_callback(request, *callback_args, **callback_kwargs)
  File "D:\tester\guest\sign\views_api.py", line 108, in add_guest
    timeArray = time.strptime(etime, '%Y-%m-%d %H:%M:%S')
  File "D:\python3.6.5\lib\_strptime.py", line 559, in _strptime_time
    tt = _strptime(data_string, format)[0]
  File "D:\python3.6.5\lib\_strptime.py", line 365, in _strptime
    data_string[found.end():])
ValueError: unconverted data remains: +00:00
2018-09-16 09:40:42,039 [Thread-1:6364] [django.server:124] [basehttp:log_message] [ERROR]- "POST /api/add_guest/ HTTP/1.1" 500 76832
2018-09-16 09:40:59,069 [Thread-1:7576] [log:104] [views_api:add_guest] [INFO]- 2018-09-15 09:31:00+00:00
2018-09-16 09:40:59,071 [Thread-1:7576] [log:107] [views_api:add_guest] [INFO]- 2018-09-15 09:31:00
2018-09-16 09:40:59,077 [Thread-1:7576] [log:116] [views_api:add_guest] [INFO]- 活动未开始.
2018-09-16 09:40:59,079 [Thread-1:7576] [django.server:124] [basehttp:log_message] [INFO]- "POST /api/add_guest/ HTTP/1.1" 200 50
2018-09-16 09:42:58,235 [Thread-1:1212] [log:102] [views_api:add_guest] [INFO]- 2018-09-15 09:31:00
2018-09-16 09:42:58,241 [Thread-1:1212] [log:111] [views_api:add_guest] [INFO]- 活动未开始.
2018-09-16 09:42:58,243 [Thread-1:1212] [django.server:124] [basehttp:log_message] [INFO]- "POST /api/add_guest/ HTTP/1.1" 200 50
2018-09-16 09:44:54,072 [Thread-1:4212] [log:102] [views_api:add_guest] [INFO]- 2018-09-15 09:31:00
2018-09-16 09:44:54,079 [Thread-1:4212] [log:109] [views_api:add_guest] [INFO]- 1537062294
2018-09-16 09:44:54,079 [Thread-1:4212] [log:112] [views_api:add_guest] [INFO]- 活动未开始.
2018-09-16 09:44:54,080 [Thread-1:4212] [django.server:124] [basehttp:log_message] [INFO]- "POST /api/add_guest/ HTTP/1.1" 200 50
2018-09-16 09:45:20,332 [Thread-1:8588] [log:102] [views_api:add_guest] [INFO]- 2018-09-15 09:31:00
2018-09-16 09:45:20,338 [Thread-1:8588] [log:105] [views_api:add_guest] [INFO]- 1536975060
2018-09-16 09:45:20,338 [Thread-1:8588] [log:110] [views_api:add_guest] [INFO]- 1537062320
2018-09-16 09:45:20,339 [Thread-1:8588] [log:113] [views_api:add_guest] [INFO]- 活动未开始.
2018-09-16 09:45:20,340 [Thread-1:8588] [django.server:124] [basehttp:log_message] [INFO]- "POST /api/add_guest/ HTTP/1.1" 200 50
2018-09-16 09:46:48,021 [Thread-1:8292] [log:102] [views_api:add_guest] [INFO]- 2018-09-16 06:57:00
2018-09-16 09:46:48,025 [Thread-1:8292] [log:105] [views_api:add_guest] [INFO]- 1537052220
2018-09-16 09:46:48,026 [Thread-1:8292] [log:110] [views_api:add_guest] [INFO]- 1537062408
2018-09-16 09:46:48,026 [Thread-1:8292] [log:113] [views_api:add_guest] [INFO]- 活动已开始.
2018-09-16 09:46:48,027 [Thread-1:8292] [django.server:124] [basehttp:log_message] [INFO]- "POST /api/add_guest/ HTTP/1.1" 200 50
2018-09-16 09:47:29,443 [Thread-3:9040] [log:102] [views_api:add_guest] [INFO]- 2018-09-16 22:57:00
2018-09-16 09:47:29,444 [Thread-3:9040] [log:105] [views_api:add_guest] [INFO]- 1537109820
2018-09-16 09:47:29,444 [Thread-3:9040] [log:110] [views_api:add_guest] [INFO]- 1537062449
2018-09-16 09:47:29,509 [Thread-3:9040] [log:120] [views_api:add_guest] [INFO]- 嘉宾添加成功！
2018-09-16 09:47:29,511 [Thread-3:9040] [django.request:135] [exception:handle_uncaught_exception] [ERROR]- Internal Server Error: /api/add_guest/
Traceback (most recent call last):
  File "D:\python3.6.5\lib\site-packages\django\core\handlers\exception.py", line 41, in inner
    response = get_response(request)
  File "D:\python3.6.5\lib\site-packages\django\core\handlers\base.py", line 198, in _get_response
    "returned None instead." % (callback.__module__, view_name)
ValueError: The view sign.views_api.add_guest didn't return an HttpResponse object. It returned None instead.
2018-09-16 09:47:29,756 [Thread-3:9040] [django.server:124] [basehttp:log_message] [ERROR]- "POST /api/add_guest/ HTTP/1.1" 500 58974
2018-09-16 09:47:53,766 [Thread-1:7988] [log:102] [views_api:add_guest] [INFO]- 2018-09-16 22:57:00
2018-09-16 09:47:53,770 [Thread-1:7988] [log:105] [views_api:add_guest] [INFO]- 1537109820
2018-09-16 09:47:53,771 [Thread-1:7988] [log:110] [views_api:add_guest] [INFO]- 1537062473
2018-09-16 09:47:53,882 [Thread-1:7988] [log:118] [views_api:add_guest] [INFO]- 手机号有点问题.
2018-09-16 09:47:53,883 [Thread-1:7988] [django.server:124] [basehttp:log_message] [INFO]- "POST /api/add_guest/ HTTP/1.1" 200 68
2018-09-16 09:49:22,218 [Thread-3:7760] [log:102] [views_api:add_guest] [INFO]- 2018-09-16 22:57:00
2018-09-16 09:49:22,219 [Thread-3:7760] [log:105] [views_api:add_guest] [INFO]- 1537109820
2018-09-16 09:49:22,220 [Thread-3:7760] [log:110] [views_api:add_guest] [INFO]- 1537062562
2018-09-16 09:49:22,273 [Thread-3:7760] [log:120] [views_api:add_guest] [INFO]- 嘉宾添加成功！
2018-09-16 09:49:22,274 [Thread-3:7760] [django.server:124] [basehttp:log_message] [INFO]- "POST /api/add_guest/ HTTP/1.1" 200 48
2018-09-16 10:05:08,332 [Thread-1:4740] [log:132] [views_api:get_guest_list] [INFO]- 参数错误，不能为空
2018-09-16 10:05:08,334 [Thread-1:4740] [django.server:124] [basehttp:log_message] [INFO]- "GET /api/get_guest_list/ HTTP/1.1" 200 52
2018-09-16 10:05:20,531 [Thread-6:4520] [log:132] [views_api:get_guest_list] [INFO]- 参数错误，不能为空
2018-09-16 10:05:20,535 [Thread-6:4520] [django.server:124] [basehttp:log_message] [INFO]- "GET /api/get_guest_list/?name=%E5%B0%8F HTTP/1.1" 200 52
2018-09-16 10:06:15,225 [Thread-7:8300] [django.server:124] [basehttp:log_message] [INFO]- "GET /admin/sign/event/add/ HTTP/1.1" 200 6003
2018-09-16 10:06:17,723 [Thread-8:4536] [django.server:124] [basehttp:log_message] [INFO]- "GET /admin/ HTTP/1.1" 200 6693
2018-09-16 10:06:19,537 [Thread-9:6392] [django.server:124] [basehttp:log_message] [INFO]- "GET /admin/sign/guest/ HTTP/1.1" 200 9508
2018-09-16 10:06:19,750 [Thread-10:6532] [django.server:124] [basehttp:log_message] [INFO]- "GET /admin/jsi18n/ HTTP/1.1" 200 7682
2018-09-16 10:06:45,398 [Thread-11:2104] [django.server:124] [basehttp:log_message] [INFO]- "GET /admin/ HTTP/1.1" 200 6693
2018-09-16 10:07:07,550 [Thread-15:6328] [django.server:124] [basehttp:log_message] [INFO]- "GET /api/get_guest_list/?eid=2&name=%E5%B0%8F%E7%B1%B3 HTTP/1.1" 200 362
2018-09-16 10:07:23,038 [Thread-16:8424] [django.server:124] [basehttp:log_message] [INFO]- "GET /api/get_guest_list/?eid=2&name=%E5%B0%8F%E7%B1%B3 HTTP/1.1" 200 362
2018-09-16 10:14:19,161 [Thread-1:5292] [django.server:124] [basehttp:log_message] [INFO]- "GET /api/get_guest_list?eid=2&name=15 HTTP/1.1" 301 0
2018-09-16 10:14:20,182 [Thread-3:8312] [log:155] [views_api:get_guest_list] [INFO]- 查询嘉宾成功！
2018-09-16 10:14:20,183 [Thread-3:8312] [django.server:124] [basehttp:log_message] [INFO]- "GET /api/get_guest_list/?eid=2&name=15 HTTP/1.1" 200 362
2018-09-16 10:14:29,412 [Thread-4:5544] [log:155] [views_api:get_guest_list] [INFO]- 查询嘉宾成功！
2018-09-16 10:14:29,414 [Thread-4:5544] [django.server:124] [basehttp:log_message] [INFO]- "GET /api/get_guest_list/?eid=2&name=15 HTTP/1.1" 200 362
2018-09-16 10:15:19,162 [Thread-7:4468] [log:158] [views_api:get_guest_list] [INFO]- 查询结果为空.
2018-09-16 10:15:19,164 [Thread-7:4468] [django.server:124] [basehttp:log_message] [INFO]- "GET /api/get_guest_list/?eid=3&name=15 HTTP/1.1" 200 54
2018-09-16 10:15:22,660 [Thread-8:2068] [log:158] [views_api:get_guest_list] [INFO]- 查询结果为空.
2018-09-16 10:15:22,662 [Thread-8:2068] [django.server:124] [basehttp:log_message] [INFO]- "GET /api/get_guest_list/?eid=4&name=15 HTTP/1.1" 200 54
2018-09-16 10:15:26,604 [Thread-9:6976] [log:158] [views_api:get_guest_list] [INFO]- 查询结果为空.
2018-09-16 10:15:26,605 [Thread-9:6976] [django.server:124] [basehttp:log_message] [INFO]- "GET /api/get_guest_list/?eid=5&name=15 HTTP/1.1" 200 54
2018-09-16 10:15:30,552 [Thread-10:5312] [log:158] [views_api:get_guest_list] [INFO]- 查询结果为空.
2018-09-16 10:15:30,555 [Thread-10:5312] [django.server:124] [basehttp:log_message] [INFO]- "GET /api/get_guest_list/?eid=6&name=15 HTTP/1.1" 200 54
2018-09-16 10:15:34,851 [Thread-11:2040] [log:158] [views_api:get_guest_list] [INFO]- 查询结果为空.
2018-09-16 10:15:34,852 [Thread-11:2040] [django.server:124] [basehttp:log_message] [INFO]- "GET /api/get_guest_list/?eid=7&name=15 HTTP/1.1" 200 54
2018-09-16 10:15:44,399 [Thread-12:7536] [log:155] [views_api:get_guest_list] [INFO]- 查询嘉宾成功！
2018-09-16 10:15:44,400 [Thread-12:7536] [django.server:124] [basehttp:log_message] [INFO]- "GET /api/get_guest_list/?eid=11&name=15 HTTP/1.1" 200 262
2018-09-16 10:15:52,779 [Thread-13:6296] [log:155] [views_api:get_guest_list] [INFO]- 查询嘉宾成功！
2018-09-16 10:15:52,780 [Thread-13:6296] [django.server:124] [basehttp:log_message] [INFO]- "GET /api/get_guest_list/?eid=11&name=15 HTTP/1.1" 200 262
2018-09-16 10:16:36,759 [Thread-1:8912] [log:155] [views_api:get_guest_list] [INFO]- 查询嘉宾成功！
2018-09-16 10:16:36,760 [Thread-1:8912] [django.server:124] [basehttp:log_message] [INFO]- "GET /api/get_guest_list/?eid=11&name=15 HTTP/1.1" 200 262
2018-09-16 10:20:22,799 [Thread-3:5516] [django.request:135] [exception:handle_uncaught_exception] [ERROR]- Internal Server Error: /api/get_guest_list/
Traceback (most recent call last):
  File "D:\python3.6.5\lib\site-packages\django\core\handlers\exception.py", line 41, in inner
    response = get_response(request)
  File "D:\python3.6.5\lib\site-packages\django\core\handlers\base.py", line 187, in _get_response
    response = self.process_exception_by_middleware(e, request)
  File "D:\python3.6.5\lib\site-packages\django\core\handlers\base.py", line 185, in _get_response
    response = wrapped_callback(request, *callback_args, **callback_kwargs)
  File "D:\tester\guest\sign\views_api.py", line 168, in get_guest_list
    guest['realname'] = result.realname
AttributeError: 'QuerySet' object has no attribute 'realname'
2018-09-16 10:20:23,041 [Thread-3:5516] [django.server:124] [basehttp:log_message] [ERROR]- "GET /api/get_guest_list/?eid=2&name=%E5%B0%8F%E7%B1%B3 HTTP/1.1" 500 67423
2018-09-16 10:20:58,223 [Thread-5:4628] [django.request:135] [exception:handle_uncaught_exception] [ERROR]- Internal Server Error: /api/get_guest_list/
Traceback (most recent call last):
  File "D:\python3.6.5\lib\site-packages\django\core\handlers\exception.py", line 41, in inner
    response = get_response(request)
  File "D:\python3.6.5\lib\site-packages\django\core\handlers\base.py", line 187, in _get_response
    response = self.process_exception_by_middleware(e, request)
  File "D:\python3.6.5\lib\site-packages\django\core\handlers\base.py", line 185, in _get_response
    response = wrapped_callback(request, *callback_args, **callback_kwargs)
  File "D:\tester\guest\sign\views_api.py", line 168, in get_guest_list
    guest['realname'] = result.realname
AttributeError: 'QuerySet' object has no attribute 'realname'
2018-09-16 10:20:58,300 [Thread-5:4628] [django.server:124] [basehttp:log_message] [ERROR]- "GET /api/get_guest_list/?eid=2&name=%E5%B0%8F%E7%B1%B3 HTTP/1.1" 500 67423
2018-09-16 10:21:12,237 [Thread-6:4728] [django.request:135] [exception:handle_uncaught_exception] [ERROR]- Internal Server Error: /api/get_guest_list/
Traceback (most recent call last):
  File "D:\python3.6.5\lib\site-packages\django\core\handlers\exception.py", line 41, in inner
    response = get_response(request)
  File "D:\python3.6.5\lib\site-packages\django\core\handlers\base.py", line 187, in _get_response
    response = self.process_exception_by_middleware(e, request)
  File "D:\python3.6.5\lib\site-packages\django\core\handlers\base.py", line 185, in _get_response
    response = wrapped_callback(request, *callback_args, **callback_kwargs)
  File "D:\tester\guest\sign\views_api.py", line 168, in get_guest_list
    guest['realname'] = result.realname
AttributeError: 'QuerySet' object has no attribute 'realname'
2018-09-16 10:21:12,325 [Thread-6:4728] [django.server:124] [basehttp:log_message] [ERROR]- "GET /api/get_guest_list/?eid=2&name=%E5%B0%8F%E7%B1%B3 HTTP/1.1" 500 70276
2018-09-16 10:23:02,580 [Thread-4:1664] [django.request:135] [exception:handle_uncaught_exception] [ERROR]- Internal Server Error: /api/get_guest_list/
Traceback (most recent call last):
  File "D:\python3.6.5\lib\site-packages\django\core\handlers\exception.py", line 41, in inner
    response = get_response(request)
  File "D:\python3.6.5\lib\site-packages\django\core\handlers\base.py", line 187, in _get_response
    response = self.process_exception_by_middleware(e, request)
  File "D:\python3.6.5\lib\site-packages\django\core\handlers\base.py", line 185, in _get_response
    response = wrapped_callback(request, *callback_args, **callback_kwargs)
  File "D:\tester\guest\sign\views_api.py", line 168, in get_guest_list
    guest['realname'] = result.realname
AttributeError: 'QuerySet' object has no attribute 'realname'
2018-09-16 10:23:02,850 [Thread-4:1664] [django.server:124] [basehttp:log_message] [ERROR]- "GET /api/get_guest_list/?eid=2&name=%E5%B0%8F%E7%B1%B3 HTTP/1.1" 500 67431
2018-09-16 10:24:59,184 [Thread-1:7036] [log:164] [views_api:get_guest_list] [INFO]- ----------------------------------------------------------------------------------------------------
2018-09-16 10:24:59,184 [Thread-1:7036] [log:165] [views_api:get_guest_list] [INFO]- <QuerySet []>
2018-09-16 10:24:59,201 [Thread-1:7036] [django.request:135] [exception:handle_uncaught_exception] [ERROR]- Internal Server Error: /api/get_guest_list/
Traceback (most recent call last):
  File "D:\python3.6.5\lib\site-packages\django\core\handlers\exception.py", line 41, in inner
    response = get_response(request)
  File "D:\python3.6.5\lib\site-packages\django\core\handlers\base.py", line 187, in _get_response
    response = self.process_exception_by_middleware(e, request)
  File "D:\python3.6.5\lib\site-packages\django\core\handlers\base.py", line 185, in _get_response
    response = wrapped_callback(request, *callback_args, **callback_kwargs)
  File "D:\tester\guest\sign\views_api.py", line 170, in get_guest_list
    guest['realname'] = result.realname
AttributeError: 'QuerySet' object has no attribute 'realname'
2018-09-16 10:24:59,417 [Thread-1:7036] [django.server:124] [basehttp:log_message] [ERROR]- "GET /api/get_guest_list/?eid=2&name=%E5%B0%8F%E7%B1%B3 HTTP/1.1" 500 67468
[2018-09-16 10:28:53,157] [views_api.py:167] [views_api:get_guest_list] [INFO]- 查询结果为空.
[2018-09-16 10:28:53,159] [basehttp.py:124] [basehttp:log_message] [INFO]- "GET /api/get_guest_list/?eid=2&name=%E5%B0%8F%E7%B1%B3 HTTP/1.1" 200 54
[2018-09-16 10:29:09,272] [exception.py:135] [exception:handle_uncaught_exception] [ERROR]- Internal Server Error: /api/get_guest_list/
Traceback (most recent call last):
  File "D:\python3.6.5\lib\site-packages\django\core\handlers\exception.py", line 41, in inner
    response = get_response(request)
  File "D:\python3.6.5\lib\site-packages\django\core\handlers\base.py", line 187, in _get_response
    response = self.process_exception_by_middleware(e, request)
  File "D:\python3.6.5\lib\site-packages\django\core\handlers\base.py", line 185, in _get_response
    response = wrapped_callback(request, *callback_args, **callback_kwargs)
  File "D:\tester\guest\sign\views_api.py", line 163, in get_guest_list
    result = Guest.objects.get(Q(phone__contains=name) | Q(realname__contains=name) & Q(event_id=eid))
  File "D:\python3.6.5\lib\site-packages\django\db\models\manager.py", line 85, in manager_method
    return getattr(self.get_queryset(), name)(*args, **kwargs)
  File "D:\python3.6.5\lib\site-packages\django\db\models\query.py", line 384, in get
    (self.model._meta.object_name, num)
sign.models.MultipleObjectsReturned: get() returned more than one Guest -- it returned 3!
[2018-09-16 10:29:09,552] [basehttp.py:124] [basehttp:log_message] [ERROR]- "GET /api/get_guest_list/?eid=2&name=%E5%B0%8F HTTP/1.1" 500 75784
[2018-09-16 10:30:24,588] [views_api.py:164] [views_api:get_guest_list] [INFO]- ----------------------------------------------------------------------------------------------------
[2018-09-16 10:30:24,590] [views_api.py:165] [views_api:get_guest_list] [INFO]- <QuerySet [<Guest: 王小虎>, <Guest: 赵小刀>, <Guest: 黄小渤>]>
[2018-09-16 10:30:24,606] [exception.py:135] [exception:handle_uncaught_exception] [ERROR]- Internal Server Error: /api/get_guest_list/
Traceback (most recent call last):
  File "D:\python3.6.5\lib\site-packages\django\core\handlers\exception.py", line 41, in inner
    response = get_response(request)
  File "D:\python3.6.5\lib\site-packages\django\core\handlers\base.py", line 187, in _get_response
    response = self.process_exception_by_middleware(e, request)
  File "D:\python3.6.5\lib\site-packages\django\core\handlers\base.py", line 185, in _get_response
    response = wrapped_callback(request, *callback_args, **callback_kwargs)
  File "D:\tester\guest\sign\views_api.py", line 170, in get_guest_list
    guest['realname'] = result.realname
AttributeError: 'QuerySet' object has no attribute 'realname'
[2018-09-16 10:30:24,855] [basehttp.py:124] [basehttp:log_message] [ERROR]- "GET /api/get_guest_list/?eid=2&name=%E5%B0%8F HTTP/1.1" 500 67403
[2018-09-16 10:37:21,709] [views_api.py:183] [views_api:get_guest_list] [INFO]- 查询嘉宾成功！
[2018-09-16 10:37:21,713] [basehttp.py:124] [basehttp:log_message] [INFO]- "GET /api/get_guest_list/?name=%E5%B0%8F HTTP/1.1" 200 898
[2018-09-16 10:37:32,912] [views_api.py:50] [views_api:get_event_list] [INFO]- 参数错误，不能为空.
[2018-09-16 10:37:32,915] [basehttp.py:124] [basehttp:log_message] [INFO]- "GET /api/get_event_list/ HTTP/1.1" 200 48
[2018-09-16 10:40:11,316] [views_api.py:65] [views_api:get_event_list] [INFO]- 查询嘉宾成功！
[2018-09-16 10:40:11,317] [basehttp.py:124] [basehttp:log_message] [INFO]- "GET /api/get_event_list/?eid=2&name=%E5%B0%8F%E7%B1%B3 HTTP/1.1" 200 201
[2018-09-16 10:40:38,820] [views_api.py:189] [views_api:get_guest_list] [INFO]- 查询结果为空.
[2018-09-16 10:40:38,823] [basehttp.py:124] [basehttp:log_message] [INFO]- "GET /api/get_guest_list/?eid=2&name=%E5%B0%8F%E7%B1%B3 HTTP/1.1" 200 54
[2018-09-16 10:40:46,974] [views_api.py:186] [views_api:get_guest_list] [INFO]- 查询嘉宾成功！
[2018-09-16 10:40:46,975] [basehttp.py:124] [basehttp:log_message] [INFO]- "GET /api/get_guest_list/?eid=2&name=%E5%B0%8F HTTP/1.1" 200 362
[2018-09-16 10:40:59,988] [views_api.py:186] [views_api:get_guest_list] [INFO]- 查询嘉宾成功！
[2018-09-16 10:40:59,989] [basehttp.py:124] [basehttp:log_message] [INFO]- "GET /api/get_guest_list/?eid=2&name=%E5%B0%8F HTTP/1.1" 200 362
[2018-09-16 10:41:32,825] [views_api.py:189] [views_api:get_guest_list] [INFO]- 查询结果为空.
[2018-09-16 10:41:32,826] [basehttp.py:124] [basehttp:log_message] [INFO]- "GET /api/get_guest_list/?eid=2&name=%E5%B9%BF%E4%B8%9C%E4%BD%9B%E5%B1%B1%E7%9A%84 HTTP/1.1" 200 54
[2018-09-16 10:41:35,890] [views_api.py:154] [views_api:get_guest_list] [INFO]- 查询嘉宾成功！
[2018-09-16 10:41:35,891] [basehttp.py:124] [basehttp:log_message] [INFO]- "GET /api/get_guest_list/?eid=2&name= HTTP/1.1" 200 362
[2018-09-16 10:41:50,362] [views_api.py:186] [views_api:get_guest_list] [INFO]- 查询嘉宾成功！
[2018-09-16 10:41:50,363] [basehttp.py:124] [basehttp:log_message] [INFO]- "GET /api/get_guest_list/?eid=2&name=%E8%B5%B5 HTTP/1.1" 200 150
[2018-09-16 10:42:48,321] [views_api.py:154] [views_api:get_guest_list] [INFO]- 查询嘉宾成功！
[2018-09-16 10:42:48,322] [basehttp.py:124] [basehttp:log_message] [INFO]- "GET /api/get_guest_list/?eid=2 HTTP/1.1" 200 362
[2018-09-16 10:42:52,410] [views_api.py:141] [views_api:get_guest_list] [INFO]- 参数错误，不能为空
[2018-09-16 10:42:52,411] [basehttp.py:124] [basehttp:log_message] [INFO]- "GET /api/get_guest_list/ HTTP/1.1" 200 52
[2018-09-16 10:43:18,796] [views_api.py:154] [views_api:get_guest_list] [INFO]- 查询嘉宾成功！
[2018-09-16 10:43:18,797] [basehttp.py:124] [basehttp:log_message] [INFO]- "GET /api/get_guest_list/?eid=2 HTTP/1.1" 200 362
[2018-09-16 11:10:20,361] [basehttp.py:124] [basehttp:log_message] [INFO]- "GET /admin/sign/guest/add/ HTTP/1.1" 200 6785
[2018-09-16 11:10:20,426] [basehttp.py:124] [basehttp:log_message] [INFO]- "GET /admin/jsi18n/ HTTP/1.1" 200 7682
[2018-09-16 11:10:22,090] [basehttp.py:124] [basehttp:log_message] [INFO]- "GET /admin/ HTTP/1.1" 200 6693
[2018-09-16 11:10:24,787] [basehttp.py:124] [basehttp:log_message] [INFO]- "GET /admin/sign/guest/ HTTP/1.1" 200 9508
[2018-09-16 11:10:25,029] [basehttp.py:124] [basehttp:log_message] [INFO]- "GET /admin/jsi18n/ HTTP/1.1" 200 7682
[2018-09-16 11:10:32,208] [basehttp.py:124] [basehttp:log_message] [INFO]- "GET /admin/sign/guest/ HTTP/1.1" 200 9508
[2018-09-16 11:10:33,277] [basehttp.py:124] [basehttp:log_message] [INFO]- "GET /admin/ HTTP/1.1" 200 6693
[2018-09-16 11:10:58,173] [basehttp.py:124] [basehttp:log_message] [INFO]- "GET /guest_manage/ HTTP/1.1" 200 5049
[2018-09-16 11:10:58,833] [basehttp.py:124] [basehttp:log_message] [INFO]- "GET /event_manage/ HTTP/1.1" 200 7146
[2018-09-16 11:11:01,440] [basehttp.py:124] [basehttp:log_message] [INFO]- "GET /event_manage/?page=2 HTTP/1.1" 200 3307
[2018-09-16 11:11:03,501] [basehttp.py:124] [basehttp:log_message] [INFO]- "GET /guest_manage/ HTTP/1.1" 200 5049
[2018-09-16 11:11:04,158] [basehttp.py:124] [basehttp:log_message] [INFO]- "GET /event_manage/ HTTP/1.1" 200 7146
[2018-09-16 15:49:06,848] [views_api.py:157] [views_api:get_guest_list] [INFO]- 查询结果为空.
[2018-09-16 15:49:06,849] [basehttp.py:124] [basehttp:log_message] [INFO]- "GET /api/get_guest_list/?eid=8888 HTTP/1.1" 200 54
[2018-09-16 15:49:37,749] [views_api.py:157] [views_api:get_guest_list] [INFO]- 查询结果为空.
[2018-09-16 15:49:37,751] [basehttp.py:124] [basehttp:log_message] [INFO]- "GET /api/get_guest_list/?eid=8888 HTTP/1.1" 200 54
[2018-09-16 15:51:29,072] [views_api.py:157] [views_api:get_guest_list] [INFO]- 查询结果为空.
[2018-09-16 15:51:29,073] [basehttp.py:124] [basehttp:log_message] [INFO]- "GET /api/get_guest_list/?eid=8888 HTTP/1.1" 200 54
[2018-09-16 15:54:35,029] [basehttp.py:124] [basehttp:log_message] [INFO]- "GET /guest_manage/ HTTP/1.1" 302 0
[2018-09-16 15:54:35,045] [basehttp.py:124] [basehttp:log_message] [INFO]- "GET /accounts/login/?next=/guest_manage/ HTTP/1.1" 200 1806
[2018-09-16 15:54:37,237] [basehttp.py:124] [basehttp:log_message] [INFO]- "POST /login_action/ HTTP/1.1" 302 0
[2018-09-16 15:54:37,435] [basehttp.py:124] [basehttp:log_message] [INFO]- "GET /event_manage/ HTTP/1.1" 200 7146
[2018-09-16 15:54:38,386] [basehttp.py:124] [basehttp:log_message] [INFO]- "GET /guest_manage/ HTTP/1.1" 200 5049
[2018-09-16 15:56:38,653] [views_api.py:157] [views_api:get_guest_list] [INFO]- 查询嘉宾成功！
[2018-09-16 15:56:38,655] [basehttp.py:124] [basehttp:log_message] [INFO]- "GET /api/get_guest_list/?eid=2 HTTP/1.1" 200 515
[2018-09-16 15:57:38,211] [basehttp.py:124] [basehttp:log_message] [INFO]- "GET /search_guest/?name=%E6%B5%8B%E8%AF%95 HTTP/1.1" 200 2668
[2018-09-16 16:01:41,803] [views_api.py:158] [views_api:get_guest_list] [INFO]- 查询结果为空.
[2018-09-16 16:01:41,804] [basehttp.py:124] [basehttp:log_message] [INFO]- "GET /api/get_guest_list/?eid=8888 HTTP/1.1" 200 54
[2018-09-16 16:02:05,543] [views_api.py:166] [views_api:get_guest_list] [INFO]- 查询结果为空.
[2018-09-16 16:02:05,544] [basehttp.py:124] [basehttp:log_message] [INFO]- "GET /api/get_guest_list/?eid=8888&phone=187 HTTP/1.1" 200 54
[2018-09-16 16:02:23,511] [views_api.py:166] [views_api:get_guest_list] [INFO]- 查询结果为空.
[2018-09-16 16:02:23,512] [basehttp.py:124] [basehttp:log_message] [INFO]- "GET /api/get_guest_list/?eid=8888&phone=187 HTTP/1.1" 200 54
[2018-09-16 16:03:07,334] [views_api.py:166] [views_api:get_guest_list] [INFO]- 查询结果为空.
[2018-09-16 16:03:07,336] [basehttp.py:124] [basehttp:log_message] [INFO]- "GET /api/get_guest_list/?eid=8888&phone=18701137212 HTTP/1.1" 200 54
[2018-09-16 16:03:15,942] [views_api.py:173] [views_api:get_guest_list] [INFO]- 查询嘉宾成功！
[2018-09-16 16:03:15,944] [basehttp.py:124] [basehttp:log_message] [INFO]- "GET /api/get_guest_list/?eid=2&phone=18701137212 HTTP/1.1" 200 152
[2018-09-16 16:03:27,755] [views_api.py:166] [views_api:get_guest_list] [INFO]- 查询结果为空.
[2018-09-16 16:03:27,756] [basehttp.py:124] [basehttp:log_message] [INFO]- "GET /api/get_guest_list/?eid=3&phone=18701137212 HTTP/1.1" 200 54
[2018-09-16 16:16:53,411] [basehttp.py:124] [basehttp:log_message] [INFO]- "GET /api/user_sign HTTP/1.1" 301 0
[2018-09-16 16:16:53,418] [views_api.py:183] [views_api:user_sign] [INFO]- 参数错误，不能为空.
[2018-09-16 16:16:53,419] [basehttp.py:124] [basehttp:log_message] [INFO]- "GET /api/user_sign/ HTTP/1.1" 200 48
[2018-09-16 16:19:16,084] [views_api.py:197] [views_api:user_sign] [INFO]- 2018-09-16 22:57:00
[2018-09-16 16:19:16,088] [views_api.py:200] [views_api:user_sign] [INFO]- 1537109820
[2018-09-16 16:19:16,088] [views_api.py:205] [views_api:user_sign] [INFO]- 1537085956
[2018-09-16 16:19:16,226] [basehttp.py:124] [basehttp:log_message] [INFO]- "POST /api/user_sign/ HTTP/1.1" 200 43
[2018-09-16 21:26:00,614] [exception.py:135] [exception:handle_uncaught_exception] [ERROR]- Internal Server Error: /api/get_guest_list/
Traceback (most recent call last):
  File "D:\python3.6.5\lib\site-packages\django\core\handlers\exception.py", line 41, in inner
    response = get_response(request)
  File "D:\python3.6.5\lib\site-packages\django\core\handlers\base.py", line 198, in _get_response
    "returned None instead." % (callback.__module__, view_name)
ValueError: The view sign.views_api.get_guest_list didn't return an HttpResponse object. It returned None instead.
[2018-09-16 21:26:00,844] [basehttp.py:124] [basehttp:log_message] [ERROR]- "GET /api/get_guest_list/?eid=8888&phone=187 HTTP/1.1" 500 58395
[2018-09-16 21:27:45,061] [views_api.py:153] [views_api:get_guest_list] [INFO]- 查询嘉宾成功！
[2018-09-16 21:27:45,064] [basehttp.py:124] [basehttp:log_message] [INFO]- "GET /api/get_guest_list/ HTTP/1.1" 200 895
[2018-09-16 21:27:54,964] [base.py:152] [base:get_response] [WARNING]- Not Found: /api/get_guest_list12
[2018-09-16 21:27:54,969] [basehttp.py:124] [basehttp:log_message] [WARNING]- "GET /api/get_guest_list12 HTTP/1.1" 404 4515
[2018-09-16 21:27:59,755] [basehttp.py:124] [basehttp:log_message] [INFO]- "GET /api/get_guest_list HTTP/1.1" 301 0
[2018-09-16 21:28:00,059] [views_api.py:153] [views_api:get_guest_list] [INFO]- 查询嘉宾成功！
[2018-09-16 21:28:00,061] [basehttp.py:124] [basehttp:log_message] [INFO]- "GET /api/get_guest_list/ HTTP/1.1" 200 895
[2018-09-16 21:30:06,912] [views_api.py:166] [views_api:get_guest_list] [INFO]- 查询嘉宾成功！
[2018-09-16 21:30:06,914] [basehttp.py:124] [basehttp:log_message] [INFO]- "GET /api/get_guest_list/?name=18 HTTP/1.1" 200 154
[2018-09-16 21:30:11,341] [views_api.py:166] [views_api:get_guest_list] [INFO]- 查询嘉宾成功！
[2018-09-16 21:30:11,342] [basehttp.py:124] [basehttp:log_message] [INFO]- "GET /api/get_guest_list/?name=15 HTTP/1.1" 200 575
[2018-09-16 21:30:24,710] [views_api.py:166] [views_api:get_guest_list] [INFO]- 查询嘉宾成功！
[2018-09-16 21:30:24,711] [basehttp.py:124] [basehttp:log_message] [INFO]- "GET /api/get_guest_list/?name=%E5%B0%8F HTTP/1.1" 200 895
[2018-09-16 21:31:44,145] [exception.py:135] [exception:handle_uncaught_exception] [ERROR]- Internal Server Error: /api/get_guest_list/
Traceback (most recent call last):
  File "D:\python3.6.5\lib\site-packages\django\core\handlers\exception.py", line 41, in inner
    response = get_response(request)
  File "D:\python3.6.5\lib\site-packages\django\core\handlers\base.py", line 187, in _get_response
    response = self.process_exception_by_middleware(e, request)
  File "D:\python3.6.5\lib\site-packages\django\core\handlers\base.py", line 185, in _get_response
    response = wrapped_callback(request, *callback_args, **callback_kwargs)
  File "D:\tester\guest\sign\views_api.py", line 169, in get_guest_list
    results = Event.objects.filter(name__contains=name).id
AttributeError: 'QuerySet' object has no attribute 'id'
[2018-09-16 21:31:44,367] [basehttp.py:124] [basehttp:log_message] [ERROR]- "GET /api/get_guest_list/?name=%E4%BC%9A%E5%B1%95 HTTP/1.1" 500 69982
[2018-09-16 21:32:38,439] [exception.py:135] [exception:handle_uncaught_exception] [ERROR]- Internal Server Error: /api/get_guest_list/
Traceback (most recent call last):
  File "D:\python3.6.5\lib\site-packages\django\core\handlers\exception.py", line 41, in inner
    response = get_response(request)
  File "D:\python3.6.5\lib\site-packages\django\core\handlers\base.py", line 198, in _get_response
    "returned None instead." % (callback.__module__, view_name)
ValueError: The view sign.views_api.get_guest_list didn't return an HttpResponse object. It returned None instead.
[2018-09-16 21:32:38,664] [basehttp.py:124] [basehttp:log_message] [ERROR]- "GET /api/get_guest_list/?name=%E4%BC%9A%E5%B1%95 HTTP/1.1" 500 61130
[2018-09-16 21:33:24,704] [exception.py:135] [exception:handle_uncaught_exception] [ERROR]- Internal Server Error: /api/get_guest_list/
Traceback (most recent call last):
  File "D:\python3.6.5\lib\site-packages\django\core\handlers\exception.py", line 41, in inner
    response = get_response(request)
  File "D:\python3.6.5\lib\site-packages\django\core\handlers\base.py", line 198, in _get_response
    "returned None instead." % (callback.__module__, view_name)
ValueError: The view sign.views_api.get_guest_list didn't return an HttpResponse object. It returned None instead.
[2018-09-16 21:33:24,763] [basehttp.py:124] [basehttp:log_message] [ERROR]- "GET /api/get_guest_list/?name=%E5%8F%91%E5%B8%83%E4%BC%9A HTTP/1.1" 500 61178
[2018-09-16 21:35:14,753] [exception.py:135] [exception:handle_uncaught_exception] [ERROR]- Internal Server Error: /api/get_guest_list/
Traceback (most recent call last):
  File "D:\python3.6.5\lib\site-packages\django\core\handlers\exception.py", line 41, in inner
    response = get_response(request)
  File "D:\python3.6.5\lib\site-packages\django\core\handlers\base.py", line 198, in _get_response
    "returned None instead." % (callback.__module__, view_name)
ValueError: The view sign.views_api.get_guest_list didn't return an HttpResponse object. It returned None instead.
[2018-09-16 21:35:14,957] [basehttp.py:124] [basehttp:log_message] [ERROR]- "GET /api/get_guest_list/?name=%E5%8F%91%E5%B8%83%E4%BC%9A HTTP/1.1" 500 61313
[2018-09-16 21:35:24,349] [exception.py:135] [exception:handle_uncaught_exception] [ERROR]- Internal Server Error: /api/get_guest_list/
Traceback (most recent call last):
  File "D:\python3.6.5\lib\site-packages\django\core\handlers\exception.py", line 41, in inner
    response = get_response(request)
  File "D:\python3.6.5\lib\site-packages\django\core\handlers\base.py", line 198, in _get_response
    "returned None instead." % (callback.__module__, view_name)
ValueError: The view sign.views_api.get_guest_list didn't return an HttpResponse object. It returned None instead.
[2018-09-16 21:35:24,464] [basehttp.py:124] [basehttp:log_message] [ERROR]- "GET /api/get_guest_list/?name=%E5%8F%91%E5%B8%83%E4%BC%9A HTTP/1.1" 500 61313
[2018-09-16 21:35:26,291] [basehttp.py:124] [basehttp:log_message] [INFO]- "GET /favicon.ico HTTP/1.1" 302 0
[2018-09-16 21:35:26,337] [basehttp.py:124] [basehttp:log_message] [INFO]- "GET /static/favicon.ico HTTP/1.1" 200 9662
[2018-09-16 21:35:34,312] [exception.py:135] [exception:handle_uncaught_exception] [ERROR]- Internal Server Error: /api/get_guest_list/
Traceback (most recent call last):
  File "D:\python3.6.5\lib\site-packages\django\core\handlers\exception.py", line 41, in inner
    response = get_response(request)
  File "D:\python3.6.5\lib\site-packages\django\core\handlers\base.py", line 198, in _get_response
    "returned None instead." % (callback.__module__, view_name)
ValueError: The view sign.views_api.get_guest_list didn't return an HttpResponse object. It returned None instead.
[2018-09-16 21:35:34,563] [basehttp.py:124] [basehttp:log_message] [ERROR]- "GET /api/get_guest_list/?name=%E5%8F%91%E5%B8%83%E4%BC%9A HTTP/1.1" 500 61313
[2018-09-16 21:35:34,793] [basehttp.py:124] [basehttp:log_message] [INFO]- "GET /favicon.ico HTTP/1.1" 302 0
[2018-09-16 21:35:35,105] [basehttp.py:124] [basehttp:log_message] [INFO]- "GET /static/favicon.ico HTTP/1.1" 200 9662
[2018-09-16 21:37:08,659] [exception.py:135] [exception:handle_uncaught_exception] [ERROR]- Internal Server Error: /api/get_guest_list/
Traceback (most recent call last):
  File "D:\python3.6.5\lib\site-packages\django\core\handlers\exception.py", line 41, in inner
    response = get_response(request)
  File "D:\python3.6.5\lib\site-packages\django\core\handlers\base.py", line 198, in _get_response
    "returned None instead." % (callback.__module__, view_name)
ValueError: The view sign.views_api.get_guest_list didn't return an HttpResponse object. It returned None instead.
[2018-09-16 21:37:08,911] [basehttp.py:124] [basehttp:log_message] [ERROR]- "GET /api/get_guest_list/?name=%E5%8F%91%E5%B8%83%E4%BC%9A HTTP/1.1" 500 61313
[2018-09-16 21:37:09,128] [basehttp.py:124] [basehttp:log_message] [INFO]- "GET /favicon.ico HTTP/1.1" 302 0
[2018-09-16 21:37:09,135] [basehttp.py:124] [basehttp:log_message] [INFO]- "GET /static/favicon.ico HTTP/1.1" 200 9662
[2018-09-16 21:37:21,722] [exception.py:135] [exception:handle_uncaught_exception] [ERROR]- Internal Server Error: /api/get_guest_list/
Traceback (most recent call last):
  File "D:\python3.6.5\lib\site-packages\django\core\handlers\exception.py", line 41, in inner
    response = get_response(request)
  File "D:\python3.6.5\lib\site-packages\django\core\handlers\base.py", line 198, in _get_response
    "returned None instead." % (callback.__module__, view_name)
ValueError: The view sign.views_api.get_guest_list didn't return an HttpResponse object. It returned None instead.
[2018-09-16 21:37:21,782] [basehttp.py:124] [basehttp:log_message] [ERROR]- "GET /api/get_guest_list/?name=%E5%8F%91%E5%B8%83%E4%BC%9A HTTP/1.1" 500 61313
[2018-09-16 21:37:22,006] [basehttp.py:124] [basehttp:log_message] [INFO]- "GET /favicon.ico HTTP/1.1" 302 0
[2018-09-16 21:37:22,015] [basehttp.py:124] [basehttp:log_message] [INFO]- "GET /static/favicon.ico HTTP/1.1" 200 9662
[2018-09-16 21:37:49,169] [exception.py:135] [exception:handle_uncaught_exception] [ERROR]- Internal Server Error: /api/get_guest_list/
Traceback (most recent call last):
  File "D:\python3.6.5\lib\site-packages\django\core\handlers\exception.py", line 41, in inner
    response = get_response(request)
  File "D:\python3.6.5\lib\site-packages\django\core\handlers\base.py", line 198, in _get_response
    "returned None instead." % (callback.__module__, view_name)
ValueError: The view sign.views_api.get_guest_list didn't return an HttpResponse object. It returned None instead.
[2018-09-16 21:37:49,227] [basehttp.py:124] [basehttp:log_message] [ERROR]- "GET /api/get_guest_list/?name=%E5%8F%91%E5%B8%83%E4%BC%9A HTTP/1.1" 500 61313
[2018-09-16 21:37:49,505] [basehttp.py:124] [basehttp:log_message] [INFO]- "GET /favicon.ico HTTP/1.1" 302 0
[2018-09-16 21:37:49,512] [basehttp.py:124] [basehttp:log_message] [INFO]- "GET /static/favicon.ico HTTP/1.1" 200 9662
[2018-09-16 21:40:49,294] [exception.py:135] [exception:handle_uncaught_exception] [ERROR]- Internal Server Error: /api/get_guest_list/
Traceback (most recent call last):
  File "D:\python3.6.5\lib\site-packages\django\core\handlers\exception.py", line 41, in inner
    response = get_response(request)
  File "D:\python3.6.5\lib\site-packages\django\core\handlers\base.py", line 187, in _get_response
    response = self.process_exception_by_middleware(e, request)
  File "D:\python3.6.5\lib\site-packages\django\core\handlers\base.py", line 185, in _get_response
    response = wrapped_callback(request, *callback_args, **callback_kwargs)
  File "D:\tester\guest\sign\views_api.py", line 172, in get_guest_list
    results = Guest.objects.get(event_id=r)
  File "D:\python3.6.5\lib\site-packages\django\db\models\manager.py", line 85, in manager_method
    return getattr(self.get_queryset(), name)(*args, **kwargs)
  File "D:\python3.6.5\lib\site-packages\django\db\models\query.py", line 384, in get
    (self.model._meta.object_name, num)
sign.models.MultipleObjectsReturned: get() returned more than one Guest -- it returned 3!
[2018-09-16 21:40:49,559] [basehttp.py:124] [basehttp:log_message] [ERROR]- "GET /api/get_guest_list/?name=%E5%8F%91%E5%B8%83%E4%BC%9A HTTP/1.1" 500 79331
[2018-09-16 21:41:26,575] [exception.py:135] [exception:handle_uncaught_exception] [ERROR]- Internal Server Error: /api/get_guest_list/
Traceback (most recent call last):
  File "D:\python3.6.5\lib\site-packages\django\core\handlers\exception.py", line 41, in inner
    response = get_response(request)
  File "D:\python3.6.5\lib\site-packages\django\core\handlers\base.py", line 198, in _get_response
    "returned None instead." % (callback.__module__, view_name)
ValueError: The view sign.views_api.get_guest_list didn't return an HttpResponse object. It returned None instead.
[2018-09-16 21:41:26,866] [basehttp.py:124] [basehttp:log_message] [ERROR]- "GET /api/get_guest_list/?name=%E5%8F%91%E5%B8%83%E4%BC%9A HTTP/1.1" 500 61313
[2018-09-16 21:41:27,081] [basehttp.py:124] [basehttp:log_message] [INFO]- "GET /favicon.ico HTTP/1.1" 302 0
[2018-09-16 21:41:27,106] [basehttp.py:124] [basehttp:log_message] [INFO]- "GET /static/favicon.ico HTTP/1.1" 200 9662
[2018-09-16 21:42:10,367] [views_api.py:181] [views_api:get_guest_list] [INFO]- 查询嘉宾成功！
[2018-09-16 21:42:10,368] [basehttp.py:124] [basehttp:log_message] [INFO]- "GET /api/get_guest_list/?name=%E5%8F%91%E5%B8%83%E4%BC%9A HTTP/1.1" 200 368
[2018-09-16 21:42:10,578] [basehttp.py:124] [basehttp:log_message] [INFO]- "GET /favicon.ico HTTP/1.1" 302 0
[2018-09-16 21:42:10,654] [basehttp.py:124] [basehttp:log_message] [INFO]- "GET /static/favicon.ico HTTP/1.1" 200 9662
[2018-09-16 21:43:36,220] [views_api.py:181] [views_api:get_guest_list] [INFO]- 查询嘉宾成功！
[2018-09-16 21:43:36,221] [basehttp.py:124] [basehttp:log_message] [INFO]- "GET /api/get_guest_list/?name=%E5%8F%91%E5%B8%83%E4%BC%9A HTTP/1.1" 200 368
[2018-09-16 21:43:36,356] [basehttp.py:124] [basehttp:log_message] [INFO]- "GET /favicon.ico HTTP/1.1" 302 0
[2018-09-16 21:43:36,379] [basehttp.py:124] [basehttp:log_message] [INFO]- "GET /static/favicon.ico HTTP/1.1" 200 9662
[2018-09-16 21:44:13,291] [views_api.py:183] [views_api:get_guest_list] [INFO]- 查询嘉宾成功！
[2018-09-16 21:44:13,293] [basehttp.py:124] [basehttp:log_message] [INFO]- "GET /api/get_guest_list/?name=%E5%8F%91%E5%B8%83%E4%BC%9A HTTP/1.1" 200 368
[2018-09-16 21:44:13,476] [basehttp.py:124] [basehttp:log_message] [INFO]- "GET /favicon.ico HTTP/1.1" 302 0
[2018-09-16 21:44:13,483] [basehttp.py:124] [basehttp:log_message] [INFO]- "GET /static/favicon.ico HTTP/1.1" 200 9662
[2018-09-16 21:45:09,768] [views_api.py:183] [views_api:get_guest_list] [INFO]- 查询嘉宾成功！
[2018-09-16 21:45:09,770] [basehttp.py:124] [basehttp:log_message] [INFO]- "GET /api/get_guest_list/?name=%E5%8F%91%E5%B8%83%E4%BC%9A HTTP/1.1" 200 368
[2018-09-16 21:45:11,560] [basehttp.py:124] [basehttp:log_message] [INFO]- "GET /favicon.ico HTTP/1.1" 302 0
[2018-09-16 21:45:11,607] [basehttp.py:124] [basehttp:log_message] [INFO]- "GET /static/favicon.ico HTTP/1.1" 200 9662
[2018-09-16 21:45:14,703] [exception.py:135] [exception:handle_uncaught_exception] [ERROR]- Internal Server Error: /api/get_guest_list/
Traceback (most recent call last):
  File "D:\python3.6.5\lib\site-packages\django\core\handlers\exception.py", line 41, in inner
    response = get_response(request)
  File "D:\python3.6.5\lib\site-packages\django\core\handlers\base.py", line 187, in _get_response
    response = self.process_exception_by_middleware(e, request)
  File "D:\python3.6.5\lib\site-packages\django\core\handlers\base.py", line 185, in _get_response
    response = wrapped_callback(request, *callback_args, **callback_kwargs)
  File "D:\tester\guest\sign\views_api.py", line 177, in get_guest_list
    for r in j:
TypeError: 'Guest' object is not iterable
[2018-09-16 21:45:14,926] [basehttp.py:124] [basehttp:log_message] [ERROR]- "GET /api/get_guest_list/?name=%E5%8F%91%E5%B8%83%E4%BC%9A HTTP/1.1" 500 70972
[2018-09-16 21:45:15,089] [basehttp.py:124] [basehttp:log_message] [INFO]- "GET /favicon.ico HTTP/1.1" 302 0
[2018-09-16 21:45:15,408] [basehttp.py:124] [basehttp:log_message] [INFO]- "GET /static/favicon.ico HTTP/1.1" 200 9662
[2018-09-16 21:45:46,343] [exception.py:135] [exception:handle_uncaught_exception] [ERROR]- Internal Server Error: /api/get_guest_list/
Traceback (most recent call last):
  File "D:\python3.6.5\lib\site-packages\django\core\handlers\exception.py", line 41, in inner
    response = get_response(request)
  File "D:\python3.6.5\lib\site-packages\django\core\handlers\base.py", line 187, in _get_response
    response = self.process_exception_by_middleware(e, request)
  File "D:\python3.6.5\lib\site-packages\django\core\handlers\base.py", line 185, in _get_response
    response = wrapped_callback(request, *callback_args, **callback_kwargs)
  File "D:\tester\guest\sign\views_api.py", line 178, in get_guest_list
    for r in j:
TypeError: 'Guest' object is not iterable
[2018-09-16 21:45:46,621] [basehttp.py:124] [basehttp:log_message] [ERROR]- "GET /api/get_guest_list/?name=%E5%8F%91%E5%B8%83%E4%BC%9A HTTP/1.1" 500 70940
[2018-09-16 21:45:46,922] [basehttp.py:124] [basehttp:log_message] [INFO]- "GET /favicon.ico HTTP/1.1" 302 0
[2018-09-16 21:45:46,931] [basehttp.py:124] [basehttp:log_message] [INFO]- "GET /static/favicon.ico HTTP/1.1" 200 9662
[2018-09-16 21:46:04,690] [exception.py:135] [exception:handle_uncaught_exception] [ERROR]- Internal Server Error: /api/get_guest_list/
Traceback (most recent call last):
  File "D:\python3.6.5\lib\site-packages\django\core\handlers\exception.py", line 41, in inner
    response = get_response(request)
  File "D:\python3.6.5\lib\site-packages\django\core\handlers\base.py", line 198, in _get_response
    "returned None instead." % (callback.__module__, view_name)
ValueError: The view sign.views_api.get_guest_list didn't return an HttpResponse object. It returned None instead.
[2018-09-16 21:46:04,917] [basehttp.py:124] [basehttp:log_message] [ERROR]- "GET /api/get_guest_list/?name=%E5%8F%91%E5%B8%83%E4%BC%9A HTTP/1.1" 500 61313
[2018-09-16 21:46:05,130] [basehttp.py:124] [basehttp:log_message] [INFO]- "GET /favicon.ico HTTP/1.1" 302 0
[2018-09-16 21:46:05,139] [basehttp.py:124] [basehttp:log_message] [INFO]- "GET /static/favicon.ico HTTP/1.1" 200 9662
[2018-09-16 21:46:25,625] [exception.py:135] [exception:handle_uncaught_exception] [ERROR]- Internal Server Error: /api/get_guest_list/
Traceback (most recent call last):
  File "D:\python3.6.5\lib\site-packages\django\core\handlers\exception.py", line 41, in inner
    response = get_response(request)
  File "D:\python3.6.5\lib\site-packages\django\core\handlers\base.py", line 198, in _get_response
    "returned None instead." % (callback.__module__, view_name)
ValueError: The view sign.views_api.get_guest_list didn't return an HttpResponse object. It returned None instead.
[2018-09-16 21:46:25,857] [basehttp.py:124] [basehttp:log_message] [ERROR]- "GET /api/get_guest_list/?name=%E5%8F%91%E5%B8%83%E4%BC%9A HTTP/1.1" 500 61313
[2018-09-16 21:46:26,072] [basehttp.py:124] [basehttp:log_message] [INFO]- "GET /favicon.ico HTTP/1.1" 302 0
[2018-09-16 21:46:26,081] [basehttp.py:124] [basehttp:log_message] [INFO]- "GET /static/favicon.ico HTTP/1.1" 200 9662
[2018-09-16 21:47:28,457] [exception.py:135] [exception:handle_uncaught_exception] [ERROR]- Internal Server Error: /api/get_guest_list/
Traceback (most recent call last):
  File "D:\python3.6.5\lib\site-packages\django\core\handlers\exception.py", line 41, in inner
    response = get_response(request)
  File "D:\python3.6.5\lib\site-packages\django\core\handlers\base.py", line 198, in _get_response
    "returned None instead." % (callback.__module__, view_name)
ValueError: The view sign.views_api.get_guest_list didn't return an HttpResponse object. It returned None instead.
[2018-09-16 21:47:28,702] [basehttp.py:124] [basehttp:log_message] [ERROR]- "GET /api/get_guest_list/?name=%E5%8F%91%E5%B8%83%E4%BC%9A HTTP/1.1" 500 61313
[2018-09-16 21:47:28,956] [basehttp.py:124] [basehttp:log_message] [INFO]- "GET /favicon.ico HTTP/1.1" 302 0
[2018-09-16 21:47:28,963] [basehttp.py:124] [basehttp:log_message] [INFO]- "GET /static/favicon.ico HTTP/1.1" 200 9662
[2018-09-16 21:48:40,270] [exception.py:135] [exception:handle_uncaught_exception] [ERROR]- Internal Server Error: /api/get_guest_list/
Traceback (most recent call last):
  File "D:\python3.6.5\lib\site-packages\django\core\handlers\exception.py", line 41, in inner
    response = get_response(request)
  File "D:\python3.6.5\lib\site-packages\django\core\handlers\base.py", line 187, in _get_response
    response = self.process_exception_by_middleware(e, request)
  File "D:\python3.6.5\lib\site-packages\django\core\handlers\base.py", line 185, in _get_response
    response = wrapped_callback(request, *callback_args, **callback_kwargs)
  File "D:\tester\guest\sign\views_api.py", line 174, in get_guest_list
    results = Guest.objects.filter(event_id=r)
UnboundLocalError: local variable 'r' referenced before assignment
[2018-09-16 21:48:40,576] [basehttp.py:124] [basehttp:log_message] [ERROR]- "GET /api/get_guest_list/?name=%E5%8F%91%E5%B8%83%E4%BC%9A HTTP/1.1" 500 70566
[2018-09-16 21:48:40,794] [basehttp.py:124] [basehttp:log_message] [INFO]- "GET /favicon.ico HTTP/1.1" 302 0
[2018-09-16 21:48:41,128] [basehttp.py:124] [basehttp:log_message] [INFO]- "GET /static/favicon.ico HTTP/1.1" 200 9662
[2018-09-16 21:49:04,834] [exception.py:135] [exception:handle_uncaught_exception] [ERROR]- Internal Server Error: /api/get_guest_list/
Traceback (most recent call last):
  File "D:\python3.6.5\lib\site-packages\django\core\handlers\exception.py", line 41, in inner
    response = get_response(request)
  File "D:\python3.6.5\lib\site-packages\django\core\handlers\base.py", line 187, in _get_response
    response = self.process_exception_by_middleware(e, request)
  File "D:\python3.6.5\lib\site-packages\django\core\handlers\base.py", line 185, in _get_response
    response = wrapped_callback(request, *callback_args, **callback_kwargs)
  File "D:\tester\guest\sign\views_api.py", line 177, in get_guest_list
    print(r.name)
AttributeError: 'QuerySet' object has no attribute 'name'
[2018-09-16 21:49:05,105] [basehttp.py:124] [basehttp:log_message] [ERROR]- "GET /api/get_guest_list/?name=%E5%8F%91%E5%B8%83%E4%BC%9A HTTP/1.1" 500 71465
[2018-09-16 21:49:05,359] [basehttp.py:124] [basehttp:log_message] [INFO]- "GET /favicon.ico HTTP/1.1" 302 0
[2018-09-16 21:49:05,395] [basehttp.py:124] [basehttp:log_message] [INFO]- "GET /static/favicon.ico HTTP/1.1" 200 9662
[2018-09-16 21:50:32,890] [exception.py:135] [exception:handle_uncaught_exception] [ERROR]- Internal Server Error: /api/get_guest_list/
Traceback (most recent call last):
  File "D:\python3.6.5\lib\site-packages\django\core\handlers\exception.py", line 41, in inner
    response = get_response(request)
  File "D:\python3.6.5\lib\site-packages\django\core\handlers\base.py", line 187, in _get_response
    response = self.process_exception_by_middleware(e, request)
  File "D:\python3.6.5\lib\site-packages\django\core\handlers\base.py", line 185, in _get_response
    response = wrapped_callback(request, *callback_args, **callback_kwargs)
  File "D:\tester\guest\sign\views_api.py", line 180, in get_guest_list
    for r in j:
TypeError: 'Guest' object is not iterable
[2018-09-16 21:50:33,183] [basehttp.py:124] [basehttp:log_message] [ERROR]- "GET /api/get_guest_list/?name=%E5%8F%91%E5%B8%83%E4%BC%9A HTTP/1.1" 500 71795
[2018-09-16 21:50:33,483] [basehttp.py:124] [basehttp:log_message] [INFO]- "GET /favicon.ico HTTP/1.1" 302 0
[2018-09-16 21:50:33,492] [basehttp.py:124] [basehttp:log_message] [INFO]- "GET /static/favicon.ico HTTP/1.1" 200 9662
[2018-09-16 21:51:30,868] [views_api.py:187] [views_api:get_guest_list] [INFO]- 查询嘉宾成功！
[2018-09-16 21:51:30,870] [basehttp.py:124] [basehttp:log_message] [INFO]- "GET /api/get_guest_list/?name=%E5%8F%91%E5%B8%83%E4%BC%9A HTTP/1.1" 200 368
[2018-09-16 21:51:31,030] [basehttp.py:124] [basehttp:log_message] [INFO]- "GET /favicon.ico HTTP/1.1" 302 0
[2018-09-16 21:51:31,037] [basehttp.py:124] [basehttp:log_message] [INFO]- "GET /static/favicon.ico HTTP/1.1" 200 9662
[2018-09-16 21:52:46,161] [exception.py:135] [exception:handle_uncaught_exception] [ERROR]- Internal Server Error: /api/get_guest_list/
Traceback (most recent call last):
  File "D:\python3.6.5\lib\site-packages\django\core\handlers\exception.py", line 41, in inner
    response = get_response(request)
  File "D:\python3.6.5\lib\site-packages\django\core\handlers\base.py", line 187, in _get_response
    response = self.process_exception_by_middleware(e, request)
  File "D:\python3.6.5\lib\site-packages\django\core\handlers\base.py", line 185, in _get_response
    response = wrapped_callback(request, *callback_args, **callback_kwargs)
  File "D:\tester\guest\sign\views_api.py", line 177, in get_guest_list
    for r in results:
TypeError: 'Guest' object is not iterable
[2018-09-16 21:52:46,392] [basehttp.py:124] [basehttp:log_message] [ERROR]- "GET /api/get_guest_list/?name=%E5%8F%91%E5%B8%83%E4%BC%9A HTTP/1.1" 500 71000
[2018-09-16 21:52:46,606] [basehttp.py:124] [basehttp:log_message] [INFO]- "GET /favicon.ico HTTP/1.1" 302 0
[2018-09-16 21:52:46,615] [basehttp.py:124] [basehttp:log_message] [INFO]- "GET /static/favicon.ico HTTP/1.1" 200 9662
[2018-09-16 21:53:24,622] [exception.py:135] [exception:handle_uncaught_exception] [ERROR]- Internal Server Error: /api/get_guest_list/
Traceback (most recent call last):
  File "D:\python3.6.5\lib\site-packages\django\core\handlers\exception.py", line 41, in inner
    response = get_response(request)
  File "D:\python3.6.5\lib\site-packages\django\core\handlers\base.py", line 187, in _get_response
    response = self.process_exception_by_middleware(e, request)
  File "D:\python3.6.5\lib\site-packages\django\core\handlers\base.py", line 185, in _get_response
    response = wrapped_callback(request, *callback_args, **callback_kwargs)
  File "D:\tester\guest\sign\views_api.py", line 179, in get_guest_list
    guest['realname'] = r.realname
UnboundLocalError: local variable 'r' referenced before assignment
[2018-09-16 21:53:24,864] [basehttp.py:124] [basehttp:log_message] [ERROR]- "GET /api/get_guest_list/?name=%E5%8F%91%E5%B8%83%E4%BC%9A HTTP/1.1" 500 71310
[2018-09-16 21:53:25,122] [basehttp.py:124] [basehttp:log_message] [INFO]- "GET /favicon.ico HTTP/1.1" 302 0
[2018-09-16 21:53:25,130] [basehttp.py:124] [basehttp:log_message] [INFO]- "GET /static/favicon.ico HTTP/1.1" 200 9662
[2018-09-16 21:54:18,915] [views_api.py:183] [views_api:get_guest_list] [INFO]- 查询嘉宾成功！
[2018-09-16 21:54:18,916] [basehttp.py:124] [basehttp:log_message] [INFO]- "GET /api/get_guest_list/?name=%E5%8F%91%E5%B8%83%E4%BC%9A HTTP/1.1" 200 895
[2018-09-16 21:54:19,133] [basehttp.py:124] [basehttp:log_message] [INFO]- "GET /favicon.ico HTTP/1.1" 302 0
[2018-09-16 21:54:19,146] [basehttp.py:124] [basehttp:log_message] [INFO]- "GET /static/favicon.ico HTTP/1.1" 200 9662
[2018-09-16 21:55:22,827] [views_api.py:183] [views_api:get_guest_list] [INFO]- 查询嘉宾成功！
[2018-09-16 21:55:22,828] [basehttp.py:124] [basehttp:log_message] [INFO]- "GET /api/get_guest_list/?name=%E5%B0%8F%E7%B1%B3 HTTP/1.1" 200 362
[2018-09-16 21:57:02,166] [views_api.py:185] [views_api:get_guest_list] [INFO]- 查询嘉宾成功！
[2018-09-16 21:57:02,167] [basehttp.py:124] [basehttp:log_message] [INFO]- "GET /api/get_guest_list/?name=%E5%B0%8F%E7%B1%B3 HTTP/1.1" 200 362
[2018-09-16 21:57:02,298] [basehttp.py:124] [basehttp:log_message] [INFO]- "GET /favicon.ico HTTP/1.1" 302 0
[2018-09-16 21:57:02,337] [basehttp.py:124] [basehttp:log_message] [INFO]- "GET /static/favicon.ico HTTP/1.1" 200 9662
[2018-09-16 21:57:21,364] [views_api.py:186] [views_api:get_guest_list] [INFO]- 查询嘉宾成功！
[2018-09-16 21:57:21,365] [basehttp.py:124] [basehttp:log_message] [INFO]- "GET /api/get_guest_list/?name=%E5%B0%8F%E7%B1%B3 HTTP/1.1" 200 362
[2018-09-16 21:57:21,503] [basehttp.py:124] [basehttp:log_message] [INFO]- "GET /favicon.ico HTTP/1.1" 302 0
[2018-09-16 21:57:21,532] [basehttp.py:124] [basehttp:log_message] [INFO]- "GET /static/favicon.ico HTTP/1.1" 200 9662
[2018-09-16 21:57:36,875] [views_api.py:156] [views_api:get_guest_list] [INFO]- 查询嘉宾成功！
[2018-09-16 21:57:36,876] [exception.py:135] [exception:handle_uncaught_exception] [ERROR]- Internal Server Error: /api/get_guest_list/
Traceback (most recent call last):
  File "D:\python3.6.5\lib\site-packages\django\core\handlers\exception.py", line 41, in inner
    response = get_response(request)
  File "D:\python3.6.5\lib\site-packages\django\core\handlers\base.py", line 187, in _get_response
    response = self.process_exception_by_middleware(e, request)
  File "D:\python3.6.5\lib\site-packages\django\core\handlers\base.py", line 185, in _get_response
    response = wrapped_callback(request, *callback_args, **callback_kwargs)
  File "D:\tester\guest\sign\views_api.py", line 157, in get_guest_list
    return JsonResponse({'status': 200, 'message': 'success!', 'data': datas})
  File "D:\python3.6.5\lib\site-packages\django\http\response.py", line 530, in __init__
    data = json.dumps(data, cls=encoder, **json_dumps_params)
  File "D:\python3.6.5\lib\json\__init__.py", line 238, in dumps
    **kw).encode(obj)
  File "D:\python3.6.5\lib\json\encoder.py", line 199, in encode
    chunks = self.iterencode(o, _one_shot=True)
  File "D:\python3.6.5\lib\json\encoder.py", line 257, in iterencode
    return _iterencode(o, 0)
  File "D:\python3.6.5\lib\site-packages\django\core\serializers\json.py", line 124, in default
    return super(DjangoJSONEncoder, self).default(o)
  File "D:\python3.6.5\lib\json\encoder.py", line 180, in default
    o.__class__.__name__)
TypeError: Object of type 'Event' is not JSON serializable
[2018-09-16 21:57:37,174] [basehttp.py:124] [basehttp:log_message] [ERROR]- "GET /api/get_guest_list/ HTTP/1.1" 500 109855
[2018-09-16 21:59:08,389] [views_api.py:157] [views_api:get_guest_list] [INFO]- 查询嘉宾成功！
[2018-09-16 21:59:08,390] [exception.py:135] [exception:handle_uncaught_exception] [ERROR]- Internal Server Error: /api/get_guest_list/
Traceback (most recent call last):
  File "D:\python3.6.5\lib\site-packages\django\core\handlers\exception.py", line 41, in inner
    response = get_response(request)
  File "D:\python3.6.5\lib\site-packages\django\core\handlers\base.py", line 187, in _get_response
    response = self.process_exception_by_middleware(e, request)
  File "D:\python3.6.5\lib\site-packages\django\core\handlers\base.py", line 185, in _get_response
    response = wrapped_callback(request, *callback_args, **callback_kwargs)
  File "D:\tester\guest\sign\views_api.py", line 158, in get_guest_list
    return JsonResponse({'status': 200, 'message': 'success!', 'data': datas})
  File "D:\python3.6.5\lib\site-packages\django\http\response.py", line 530, in __init__
    data = json.dumps(data, cls=encoder, **json_dumps_params)
  File "D:\python3.6.5\lib\json\__init__.py", line 238, in dumps
    **kw).encode(obj)
  File "D:\python3.6.5\lib\json\encoder.py", line 199, in encode
    chunks = self.iterencode(o, _one_shot=True)
  File "D:\python3.6.5\lib\json\encoder.py", line 257, in iterencode
    return _iterencode(o, 0)
  File "D:\python3.6.5\lib\site-packages\django\core\serializers\json.py", line 124, in default
    return super(DjangoJSONEncoder, self).default(o)
  File "D:\python3.6.5\lib\json\encoder.py", line 180, in default
    o.__class__.__name__)
TypeError: Object of type 'Event' is not JSON serializable
[2018-09-16 21:59:08,710] [basehttp.py:124] [basehttp:log_message] [ERROR]- "GET /api/get_guest_list/ HTTP/1.1" 500 109990
[2018-09-16 21:59:08,963] [basehttp.py:124] [basehttp:log_message] [INFO]- "GET /favicon.ico HTTP/1.1" 302 0
[2018-09-16 21:59:08,972] [basehttp.py:124] [basehttp:log_message] [INFO]- "GET /static/favicon.ico HTTP/1.1" 200 9662
[2018-09-16 21:59:35,082] [views_api.py:155] [views_api:get_guest_list] [INFO]- 查询嘉宾成功！
[2018-09-16 21:59:35,084] [basehttp.py:124] [basehttp:log_message] [INFO]- "GET /api/get_guest_list/ HTTP/1.1" 200 1307
[2018-09-16 21:59:35,321] [basehttp.py:124] [basehttp:log_message] [INFO]- "GET /favicon.ico HTTP/1.1" 302 0
[2018-09-16 21:59:35,355] [basehttp.py:124] [basehttp:log_message] [INFO]- "GET /static/favicon.ico HTTP/1.1" 200 9662
[2018-09-16 22:02:39,147] [views_api.py:189] [views_api:get_guest_list] [INFO]- 查询嘉宾成功！
[2018-09-16 22:02:39,149] [basehttp.py:124] [basehttp:log_message] [INFO]- "GET /api/get_guest_list/?name=%E5%8F%91%E5%B8%83%E4%BC%9A HTTP/1.1" 200 1307
[2018-09-16 22:02:44,640] [views_api.py:189] [views_api:get_guest_list] [INFO]- 查询嘉宾成功！
[2018-09-16 22:02:44,642] [basehttp.py:124] [basehttp:log_message] [INFO]- "GET /api/get_guest_list/?name=max HTTP/1.1" 200 515
[2018-09-16 22:02:51,959] [views_api.py:192] [views_api:get_guest_list] [INFO]- 查询结果为空.
[2018-09-16 22:02:51,960] [basehttp.py:124] [basehttp:log_message] [INFO]- "GET /api/get_guest_list/?name=max1 HTTP/1.1" 200 54
[2018-09-16 22:02:56,799] [views_api.py:155] [views_api:get_guest_list] [INFO]- 查询嘉宾成功！
[2018-09-16 22:02:56,800] [basehttp.py:124] [basehttp:log_message] [INFO]- "GET /api/get_guest_list/?name HTTP/1.1" 200 1307
[2018-09-16 22:03:04,492] [views_api.py:192] [views_api:get_guest_list] [INFO]- 查询结果为空.
[2018-09-16 22:03:04,493] [basehttp.py:124] [basehttp:log_message] [INFO]- "GET /api/get_guest_list/?name=wo HTTP/1.1" 200 54
[2018-09-16 22:03:17,423] [views_api.py:192] [views_api:get_guest_list] [INFO]- 查询结果为空.
[2018-09-16 22:03:17,424] [basehttp.py:124] [basehttp:log_message] [INFO]- "GET /api/get_guest_list/?name=! HTTP/1.1" 200 54
[2018-09-16 22:11:10,144] [basehttp.py:124] [basehttp:log_message] [INFO]- "GET /search_guest/?name= HTTP/1.1" 200 5066
[2018-09-16 22:11:12,072] [basehttp.py:124] [basehttp:log_message] [INFO]- "GET /search_guest/?name= HTTP/1.1" 200 5066
[2018-09-16 22:11:21,615] [basehttp.py:124] [basehttp:log_message] [INFO]- "GET /search_guest/?name=%E5%8F%91%E5%B8%83%E4%BC%9A HTTP/1.1" 200 2689
[2018-09-16 22:11:54,343] [exception.py:135] [exception:handle_uncaught_exception] [ERROR]- Internal Server Error: /search_guest/
Traceback (most recent call last):
  File "D:\python3.6.5\lib\site-packages\django\core\handlers\exception.py", line 41, in inner
    response = get_response(request)
  File "D:\python3.6.5\lib\site-packages\django\core\handlers\base.py", line 187, in _get_response
    response = self.process_exception_by_middleware(e, request)
  File "D:\python3.6.5\lib\site-packages\django\core\handlers\base.py", line 185, in _get_response
    response = wrapped_callback(request, *callback_args, **callback_kwargs)
  File "D:\python3.6.5\lib\site-packages\django\contrib\auth\decorators.py", line 23, in _wrapped_view
    return view_func(request, *args, **kwargs)
  File "D:\tester\guest\sign\views.py", line 74, in search_guest
    guest_list = Guest.objects.get(event_id=event_id)
  File "D:\python3.6.5\lib\site-packages\django\db\models\manager.py", line 85, in manager_method
    return getattr(self.get_queryset(), name)(*args, **kwargs)
  File "D:\python3.6.5\lib\site-packages\django\db\models\query.py", line 384, in get
    (self.model._meta.object_name, num)
sign.models.MultipleObjectsReturned: get() returned more than one Guest -- it returned 3!
[2018-09-16 22:11:54,615] [basehttp.py:124] [basehttp:log_message] [ERROR]- "GET /search_guest/?name=%E5%8F%91%E5%B8%83%E4%BC%9A HTTP/1.1" 500 84047
[2018-09-16 22:12:10,826] [basehttp.py:124] [basehttp:log_message] [INFO]- "GET /search_guest/?name=%E5%8F%91%E5%B8%83%E4%BC%9A HTTP/1.1" 200 3296
[2018-09-16 22:12:11,051] [basehttp.py:124] [basehttp:log_message] [INFO]- "GET /favicon.ico HTTP/1.1" 302 0
[2018-09-16 22:12:11,083] [basehttp.py:124] [basehttp:log_message] [INFO]- "GET /static/favicon.ico HTTP/1.1" 200 9662
[2018-09-16 22:17:07,400] [basehttp.py:124] [basehttp:log_message] [INFO]- "GET /search_guest/?name=%E5%8F%91%E5%B8%83%E4%BC%9A HTTP/1.1" 200 2689
[2018-09-16 22:17:42,586] [basehttp.py:124] [basehttp:log_message] [INFO]- "GET /search_guest/?name=%E5%B0%8F HTTP/1.1" 200 5076
[2018-09-16 22:18:23,081] [basehttp.py:124] [basehttp:log_message] [INFO]- "GET /search_guest/?name=%E5%8F%91%E5%B8%83%E4%BC%9A HTTP/1.1" 200 5306
[2018-09-16 22:18:51,630] [basehttp.py:124] [basehttp:log_message] [INFO]- "GET /search_guest/?name=%E5%8F%91%E5%B8%83%E4%BC%9A HTTP/1.1" 200 3397
[2018-09-16 22:19:12,837] [basehttp.py:124] [basehttp:log_message] [INFO]- "GET /search_guest/?name=%E5%8F%91%E5%B8%83%E4%BC%9A HTTP/1.1" 200 3397
[2018-09-16 22:19:13,017] [basehttp.py:124] [basehttp:log_message] [INFO]- "GET /favicon.ico HTTP/1.1" 302 0
[2018-09-16 22:19:13,029] [basehttp.py:124] [basehttp:log_message] [INFO]- "GET /static/favicon.ico HTTP/1.1" 200 9662
[2018-09-16 22:20:30,254] [basehttp.py:124] [basehttp:log_message] [INFO]- "GET /search_guest/?name=%E5%8F%91%E5%B8%83%E4%BC%9A HTTP/1.1" 200 2689
[2018-09-16 22:20:30,399] [basehttp.py:124] [basehttp:log_message] [INFO]- "GET /favicon.ico HTTP/1.1" 302 0
[2018-09-16 22:20:30,429] [basehttp.py:124] [basehttp:log_message] [INFO]- "GET /static/favicon.ico HTTP/1.1" 200 9662
[2018-09-16 22:21:19,070] [basehttp.py:124] [basehttp:log_message] [INFO]- "GET /search_guest/?name=%E5%8F%91%E5%B8%83%E4%BC%9A HTTP/1.1" 200 2689
[2018-09-16 22:21:19,259] [basehttp.py:124] [basehttp:log_message] [INFO]- "GET /favicon.ico HTTP/1.1" 302 0
[2018-09-16 22:21:19,287] [basehttp.py:124] [basehttp:log_message] [INFO]- "GET /static/favicon.ico HTTP/1.1" 200 9662
[2018-09-16 22:21:47,512] [basehttp.py:124] [basehttp:log_message] [INFO]- "GET /search_guest/?name=%E5%8F%91%E5%B8%83%E4%BC%9A HTTP/1.1" 200 5082
[2018-09-16 22:21:47,652] [basehttp.py:124] [basehttp:log_message] [INFO]- "GET /favicon.ico HTTP/1.1" 302 0
[2018-09-16 22:21:47,683] [basehttp.py:124] [basehttp:log_message] [INFO]- "GET /static/favicon.ico HTTP/1.1" 200 9662
[2018-09-16 22:27:08,168] [basehttp.py:124] [basehttp:log_message] [INFO]- "GET /search_guest/?name=%E5%8F%91%E5%B8%83%E4%BC%9A HTTP/1.1" 200 2689
[2018-09-16 22:27:08,381] [basehttp.py:124] [basehttp:log_message] [INFO]- "GET /favicon.ico HTTP/1.1" 302 0
[2018-09-16 22:27:08,421] [basehttp.py:124] [basehttp:log_message] [INFO]- "GET /static/favicon.ico HTTP/1.1" 200 9662
[2018-09-16 22:28:24,428] [basehttp.py:124] [basehttp:log_message] [INFO]- "GET /search_guest/?name=%E5%8F%91%E5%B8%83%E4%BC%9A HTTP/1.1" 200 3296
[2018-09-16 22:31:47,505] [basehttp.py:124] [basehttp:log_message] [INFO]- "GET /search_guest/?name=%E5%8F%91%E5%B8%83%E4%BC%9A HTTP/1.1" 200 5082
[2018-09-16 22:31:47,662] [basehttp.py:124] [basehttp:log_message] [INFO]- "GET /favicon.ico HTTP/1.1" 302 0
[2018-09-16 22:31:47,692] [basehttp.py:124] [basehttp:log_message] [INFO]- "GET /static/favicon.ico HTTP/1.1" 200 9662
[2018-09-16 22:31:53,711] [basehttp.py:124] [basehttp:log_message] [INFO]- "GET /search_guest/?name=%E5%8F%91%E5%B8%83%E4%BC%9A&&page=1 HTTP/1.1" 200 5082
[2018-09-16 22:32:08,274] [basehttp.py:124] [basehttp:log_message] [INFO]- "GET /search_guest/?name=i HTTP/1.1" 200 3577
[2018-09-16 22:34:20,720] [basehttp.py:124] [basehttp:log_message] [INFO]- "GET /event_manage/ HTTP/1.1" 200 7146
[2018-09-16 22:34:21,928] [basehttp.py:124] [basehttp:log_message] [INFO]- "GET /guest_manage/ HTTP/1.1" 200 5066
[2018-09-16 22:34:24,432] [basehttp.py:124] [basehttp:log_message] [INFO]- "GET /search_guest/?name= HTTP/1.1" 200 5066
[2018-09-16 22:34:26,975] [basehttp.py:124] [basehttp:log_message] [INFO]- "GET /search_guest/?name= HTTP/1.1" 200 5066
[2018-09-16 22:34:30,713] [basehttp.py:124] [basehttp:log_message] [INFO]- "GET /search_guest/?name= HTTP/1.1" 200 5066
[2018-09-16 22:34:31,550] [basehttp.py:124] [basehttp:log_message] [INFO]- "GET /search_guest/?name= HTTP/1.1" 200 5066
[2018-09-16 22:34:31,837] [basehttp.py:124] [basehttp:log_message] [INFO]- "GET /search_guest/?name= HTTP/1.1" 200 5066
[2018-09-16 22:34:32,142] [basehttp.py:124] [basehttp:log_message] [INFO]- "GET /search_guest/?name= HTTP/1.1" 200 5066
[2018-09-16 22:34:34,644] [basehttp.py:124] [basehttp:log_message] [INFO]- "GET /event_manage/ HTTP/1.1" 200 7146
[2018-09-16 22:34:36,873] [basehttp.py:124] [basehttp:log_message] [INFO]- "GET /event_manage/?page=2 HTTP/1.1" 200 3307
[2018-09-16 22:34:39,401] [basehttp.py:124] [basehttp:log_message] [INFO]- "GET /sign_index/11/ HTTP/1.1" 200 2097
[2018-09-16 22:34:42,427] [basehttp.py:124] [basehttp:log_message] [INFO]- "GET /event_manage/ HTTP/1.1" 200 7146
[2018-09-16 22:34:44,002] [basehttp.py:124] [basehttp:log_message] [INFO]- "GET /sign_index/1/ HTTP/1.1" 200 2091
[2018-09-16 22:34:45,403] [basehttp.py:124] [basehttp:log_message] [INFO]- "GET /event_manage/ HTTP/1.1" 200 7146
[2018-09-16 22:34:48,557] [basehttp.py:124] [basehttp:log_message] [INFO]- "GET /logout/ HTTP/1.1" 302 0
[2018-09-16 22:34:48,760] [basehttp.py:124] [basehttp:log_message] [INFO]- "GET /index/ HTTP/1.1" 200 1806
[2018-09-16 22:34:57,849] [basehttp.py:124] [basehttp:log_message] [INFO]- "POST /login_action/ HTTP/1.1" 302 0
[2018-09-16 22:34:57,879] [basehttp.py:124] [basehttp:log_message] [INFO]- "GET /event_manage/ HTTP/1.1" 200 7146
[2018-09-16 22:35:08,210] [basehttp.py:124] [basehttp:log_message] [INFO]- "GET /search_name/?name=%E6%B5%8B%E8%AF%95 HTTP/1.1" 200 2659
[2018-09-16 22:35:16,481] [basehttp.py:124] [basehttp:log_message] [INFO]- "GET /search_name/?name= HTTP/1.1" 200 7146
[2018-09-16 22:35:17,989] [basehttp.py:124] [basehttp:log_message] [INFO]- "GET /guest_manage/ HTTP/1.1" 200 5066
[2018-09-16 22:35:19,550] [basehttp.py:124] [basehttp:log_message] [INFO]- "GET /event_manage/ HTTP/1.1" 200 7146
[2018-09-16 22:40:36,880] [basehttp.py:124] [basehttp:log_message] [INFO]- "GET /event_manage/ HTTP/1.1" 200 7146
[2018-09-16 22:49:01,676] [views_api.py:26] [views_api:add_event] [INFO]- 发布会id已经存在.
[2018-09-16 22:49:01,677] [basehttp.py:124] [basehttp:log_message] [INFO]- "POST /api/add_event/ HTTP/1.1" 200 56
[2018-09-16 22:49:02,745] [views_api.py:26] [views_api:add_event] [INFO]- 发布会id已经存在.
[2018-09-16 22:49:02,746] [basehttp.py:124] [basehttp:log_message] [INFO]- "POST /api/add_event/ HTTP/1.1" 200 56
[2018-09-16 22:49:03,815] [views_api.py:26] [views_api:add_event] [INFO]- 发布会id已经存在.
[2018-09-16 22:49:03,816] [basehttp.py:124] [basehttp:log_message] [INFO]- "POST /api/add_event/ HTTP/1.1" 200 56
[2018-09-16 22:51:51,346] [views_api.py:26] [views_api:add_event] [INFO]- 发布会id已经存在.
[2018-09-16 22:51:51,349] [basehttp.py:124] [basehttp:log_message] [INFO]- "POST /api/add_event/ HTTP/1.1" 200 56
[2018-09-16 22:51:52,446] [views_api.py:26] [views_api:add_event] [INFO]- 发布会id已经存在.
[2018-09-16 22:51:52,448] [basehttp.py:124] [basehttp:log_message] [INFO]- "POST /api/add_event/ HTTP/1.1" 200 56
[2018-09-16 22:51:53,540] [views_api.py:26] [views_api:add_event] [INFO]- 发布会id已经存在.
[2018-09-16 22:51:53,541] [basehttp.py:124] [basehttp:log_message] [INFO]- "POST /api/add_event/ HTTP/1.1" 200 56
[2018-09-16 22:53:03,619] [views_api.py:26] [views_api:add_event] [INFO]- 发布会id已经存在.
[2018-09-16 22:53:03,621] [basehttp.py:124] [basehttp:log_message] [INFO]- "POST /api/add_event/ HTTP/1.1" 200 56
[2018-09-16 22:56:24,190] [views_api.py:26] [views_api:add_event] [INFO]- 发布会id已经存在.
[2018-09-16 22:56:24,192] [basehttp.py:124] [basehttp:log_message] [INFO]- "POST /api/add_event/ HTTP/1.1" 200 56
[2018-09-16 22:56:25,305] [views_api.py:26] [views_api:add_event] [INFO]- 发布会id已经存在.
[2018-09-16 22:56:25,307] [basehttp.py:124] [basehttp:log_message] [INFO]- "POST /api/add_event/ HTTP/1.1" 200 56
[2018-09-16 22:56:26,394] [views_api.py:26] [views_api:add_event] [INFO]- 发布会id已经存在.
[2018-09-16 22:56:26,395] [basehttp.py:124] [basehttp:log_message] [INFO]- "POST /api/add_event/ HTTP/1.1" 200 56
[2018-09-16 22:59:49,195] [views_api.py:26] [views_api:add_event] [INFO]- 发布会id已经存在.
[2018-09-16 22:59:49,196] [basehttp.py:124] [basehttp:log_message] [INFO]- "POST /api/add_event/ HTTP/1.1" 200 56
[2018-09-16 22:59:50,287] [views_api.py:26] [views_api:add_event] [INFO]- 发布会id已经存在.
[2018-09-16 22:59:50,289] [basehttp.py:124] [basehttp:log_message] [INFO]- "POST /api/add_event/ HTTP/1.1" 200 56
[2018-09-16 22:59:51,386] [views_api.py:26] [views_api:add_event] [INFO]- 发布会id已经存在.
[2018-09-16 22:59:51,388] [basehttp.py:124] [basehttp:log_message] [INFO]- "POST /api/add_event/ HTTP/1.1" 200 56
[2018-09-16 23:10:14,424] [base.py:152] [base:get_response] [WARNING]- Not Found: /
[2018-09-16 23:10:14,426] [basehttp.py:124] [basehttp:log_message] [WARNING]- "GET / HTTP/1.1" 404 3612
[2018-09-16 23:10:20,478] [basehttp.py:124] [basehttp:log_message] [INFO]- "GET /index/ HTTP/1.1" 200 1806
[2018-09-16 23:10:22,827] [basehttp.py:124] [basehttp:log_message] [INFO]- "POST /login_action/ HTTP/1.1" 302 0
[2018-09-16 23:10:23,107] [basehttp.py:124] [basehttp:log_message] [INFO]- "GET /event_manage/ HTTP/1.1" 200 7146
[2018-09-16 23:11:10,455] [basehttp.py:124] [basehttp:log_message] [INFO]- "GET /event_manage/ HTTP/1.1" 200 7172
[2018-09-16 23:11:10,587] [basehttp.py:124] [basehttp:log_message] [INFO]- "GET /favicon.ico HTTP/1.1" 302 0
[2018-09-16 23:11:10,661] [basehttp.py:124] [basehttp:log_message] [INFO]- "GET /static/favicon.ico HTTP/1.1" 200 9662
[2018-09-16 23:11:13,612] [basehttp.py:124] [basehttp:log_message] [INFO]- "GET /event_manage/?page=2 HTTP/1.1" 200 3333
[2018-09-16 23:11:15,836] [basehttp.py:124] [basehttp:log_message] [INFO]- "GET /event_manage/?page=1 HTTP/1.1" 200 7172
[2018-09-16 23:11:18,898] [basehttp.py:124] [basehttp:log_message] [INFO]- "GET /event_manage/?page=2 HTTP/1.1" 200 3333
[2018-09-16 23:11:27,315] [basehttp.py:124] [basehttp:log_message] [INFO]- "GET /event_manage/?page=2 HTTP/1.1" 200 3332
[2018-09-16 23:11:27,596] [basehttp.py:124] [basehttp:log_message] [INFO]- "GET /favicon.ico HTTP/1.1" 302 0
[2018-09-16 23:11:27,907] [basehttp.py:124] [basehttp:log_message] [INFO]- "GET /static/favicon.ico HTTP/1.1" 200 9662
[2018-09-16 23:11:29,238] [basehttp.py:124] [basehttp:log_message] [INFO]- "GET /event_manage/?page=1 HTTP/1.1" 200 7171
[2018-09-16 23:11:31,593] [basehttp.py:124] [basehttp:log_message] [INFO]- "GET /event_manage/?page=2 HTTP/1.1" 200 3332
[2018-09-16 23:11:36,577] [basehttp.py:124] [basehttp:log_message] [INFO]- "GET /event_manage/?page=1 HTTP/1.1" 200 7171
[2018-09-16 23:11:49,748] [basehttp.py:124] [basehttp:log_message] [INFO]- "GET /guest_manage/ HTTP/1.1" 200 5066
[2018-09-16 23:12:24,299] [basehttp.py:124] [basehttp:log_message] [INFO]- "GET /guest_manage/ HTTP/1.1" 200 5091
[2018-09-16 23:12:24,433] [basehttp.py:124] [basehttp:log_message] [INFO]- "GET /favicon.ico HTTP/1.1" 302 0
[2018-09-16 23:12:24,514] [basehttp.py:124] [basehttp:log_message] [INFO]- "GET /static/favicon.ico HTTP/1.1" 200 9662
[2018-09-16 23:12:29,118] [basehttp.py:124] [basehttp:log_message] [INFO]- "GET /event_manage/ HTTP/1.1" 200 7171
[2018-09-16 23:12:31,137] [basehttp.py:124] [basehttp:log_message] [INFO]- "GET /guest_manage/ HTTP/1.1" 200 5091
[2018-09-16 23:12:41,604] [basehttp.py:124] [basehttp:log_message] [INFO]- "GET /search_guest/?name=%E4%BC%9A HTTP/1.1" 200 5101
[2018-09-16 23:12:46,635] [basehttp.py:124] [basehttp:log_message] [INFO]- "GET /search_guest/?name=%E4%BC%9A HTTP/1.1" 200 5101
[2018-09-16 23:12:46,723] [basehttp.py:124] [basehttp:log_message] [INFO]- "GET /favicon.ico HTTP/1.1" 302 0
[2018-09-16 23:12:47,034] [basehttp.py:124] [basehttp:log_message] [INFO]- "GET /static/favicon.ico HTTP/1.1" 200 9662
[2018-09-16 23:12:48,716] [basehttp.py:124] [basehttp:log_message] [INFO]- "GET /search_guest/?name=%E4%BC%9A HTTP/1.1" 200 5101
[2018-09-16 23:12:48,969] [basehttp.py:124] [basehttp:log_message] [INFO]- "GET /favicon.ico HTTP/1.1" 302 0
[2018-09-16 23:12:49,276] [basehttp.py:124] [basehttp:log_message] [INFO]- "GET /static/favicon.ico HTTP/1.1" 200 9662
[2018-09-16 23:12:50,167] [basehttp.py:124] [basehttp:log_message] [INFO]- "GET /search_guest/?name=%E4%BC%9A HTTP/1.1" 200 5101
[2018-09-16 23:12:50,388] [basehttp.py:124] [basehttp:log_message] [INFO]- "GET /favicon.ico HTTP/1.1" 302 0
[2018-09-16 23:12:50,698] [basehttp.py:124] [basehttp:log_message] [INFO]- "GET /static/favicon.ico HTTP/1.1" 200 9662
[2018-09-16 23:12:51,351] [basehttp.py:124] [basehttp:log_message] [INFO]- "GET /search_guest/?name=%E4%BC%9A HTTP/1.1" 200 5101
[2018-09-16 23:12:51,597] [basehttp.py:124] [basehttp:log_message] [INFO]- "GET /favicon.ico HTTP/1.1" 302 0
[2018-09-16 23:12:51,907] [basehttp.py:124] [basehttp:log_message] [INFO]- "GET /static/favicon.ico HTTP/1.1" 200 9662
[2018-09-16 23:12:52,219] [basehttp.py:124] [basehttp:log_message] [INFO]- "GET /search_guest/?name=%E4%BC%9A HTTP/1.1" 200 5101
[2018-09-16 23:12:52,302] [basehttp.py:124] [basehttp:log_message] [INFO]- "GET /favicon.ico HTTP/1.1" 302 0
[2018-09-16 23:12:52,616] [basehttp.py:124] [basehttp:log_message] [INFO]- "GET /static/favicon.ico HTTP/1.1" 200 9662
[2018-09-16 23:12:57,366] [basehttp.py:124] [basehttp:log_message] [INFO]- "GET /search_guest/?name=%E5%B0%8F HTTP/1.1" 200 5101
[2018-09-16 23:12:58,270] [basehttp.py:124] [basehttp:log_message] [INFO]- "GET /search_guest/?name= HTTP/1.1" 200 5091
[2018-09-16 23:12:59,418] [basehttp.py:124] [basehttp:log_message] [INFO]- "GET /search_guest/?name= HTTP/1.1" 200 5091
[2018-09-16 23:12:59,966] [basehttp.py:124] [basehttp:log_message] [INFO]- "GET /search_guest/?name= HTTP/1.1" 200 5091
[2018-09-16 23:13:14,480] [basehttp.py:124] [basehttp:log_message] [INFO]- "GET /search_guest/ HTTP/1.1" 200 5091
[2018-09-16 23:13:30,661] [views_api.py:185] [views_api:get_guest_list] [INFO]- 查询嘉宾成功！
[2018-09-16 23:13:30,663] [basehttp.py:124] [basehttp:log_message] [INFO]- "GET /api/get_guest_list/?name=%E5%8F%91%E5%B8%83%E4%BC%9A HTTP/1.1" 200 1307
